Workbook

Sheet Cover Page
B5: Return on Investment Calculator
B7: Value Consulting - Business Case
B10: Client Name: | C10: SeABank Vietnam
B12: Date: | C12: 2026-02-06
B14: Currency: | C14: USD
B16: Analysis Period: | C16: 5 Years
B18: Selected Scenario: | C18: Moderate
B20: Discount Rate: | C20: 0.1
B24: DATA SOURCE LEGEND
B26: Green | C26: From transcript/client data
B27: Yellow | C27: Estimate - requires validation
B28: Blue | C28: Backbase benchmark
B29: Red border | C29: Low confidence - critical validation

Sheet Instructions
B2: ROI Model Instructions
B5: OVERVIEW
B6: This ROI model calculates value by JOURNEY with LIVE FORMULAS.
B7: All downstream calculations update automatically when inputs change.
B9: HOW FORMULAS WORK
B10: • Blue cells = Editable inputs (change these to update the model)
B11: • White cells with formulas = Calculated automatically
B12: • Change the Scenario on the Cashflows sheet to switch between Conservative/Moderate/Aggressive
B14: JOURNEY-BASED ANALYSIS
B15: • Customer Onboarding - Revenue uplift + Cost reduction from digital onboarding
B16: • Loan Origination - Revenue uplift + Cost reduction from digital lending
B17: • Customer Servicing - Cost avoidance from channel shift (Branch, Call Center, Back Office)
... B40: 5. Review Assumptions sheet with client stakeholders

Sheet Table of Contents
B3: Table of Contents
B5: Section 1 | C5: Bank Profile
C6: Bank financial data from public sources (direct + derived metrics)
B7: Section 2 | C7: Results Dashboard
C8: Return on Investment, NPV, IRR
B9: Section 3 | C9: Scenario Backup
C10: Conservative / Moderate / Aggressive curves
B11: Section 4 | C11: Journey Inputs
C12: All inputs with sources and confidence
B13: Section 5 | C13: Journey Analysis
C14: Revenue + Cost benefit calculations (formulas)
B15: Section 6 | C15: Servicing Analysis
C16: Branch / Call Center / Back Office (formulas)
B17: Section 7 | C17: Cash Flows
C18: 5-year projections with scenario switching
B19: Section 8 | C19: Assumptions & Data Gaps
C20: Assumptions Register + Validation Needs

Sheet Results Dashboard
B2: Results Dashboard
B4: Bank Overview (from Bank Profile)
B5: Metric | C5: Value
B6: Total Customers | C6: ='Bank Profile'!$C$14
B7: Annual Revenue | C7: ='Bank Profile'!$C$15
B8: Cost-to-Income Ratio | C8: ='Bank Profile'!$C$17
B9: Total FTE | C9: ='Bank Profile'!$C$18
B10: FTE Rate ($/hr) | C10: ='Bank Profile'!$C$23
B12: Financial Metrics - 5 Year Projections
B13: All values below are live formulas referencing the Cashflows sheet.
B15: Total 5-Year Benefits | C15: =Cashflows!C31
B17: Total 5-Year Investment | C17: =Cashflows!C30
B19: Net Benefit | C19: =Cashflows!C32
B21: ROI | C21: =Cashflows!C33
B23: Net Present Value (NPV) | C23: =Cashflows!C34
B25: Internal Rate of Return (IRR) | C25: =Cashflows!C35
B27: Payback Period (years) | C27: =Cashflows!C36
B30: Benefits by Journey (Annual Steady State)
B32: Journey | C32: Annual Benefit
B33: Digital Customer Onboarding (CASA) | C33: ='Journey Analysis'!C18
B34: Loan Origination (Personal & SME) | C34: ='Journey Analysis'!C32
B35: Customer Servicing | C35: ='Servicing Analysis'!H27
B36: TOTAL | C36: =SUM(C33:C35)

Sheet Cashflows
B1: 5 Year Cashflows & ROI
B3: Scenario: | C3: Moderate
B4: Discount Rate (WACC): | C4: 0.1
B6: LOADING CURVES (Scenario-Driven)
C7: Year 1 | D7: Year 2 | E7: Year 3 | F7: Year 4 | G7: Year 5
B8: Implementation % | C8: =IF($C$3="Conservative",'Scenario Backup'!C5,IF($C$3="Moderate",'Scenario Backup'!C11,'Scenario Backup'!C17)) | D8: =IF($C$3="Conservative",'Scenario Backup'!D5,IF($C$3="Moderate",'Scenario Backup'!D11,'Scenario Backup'!D17)) | E8: =IF($C$3="Conservative",'Scenario Backup'!E5,IF($C$3="Moderate",'Scenario Backup'!E11,'Scenario Backup'!E17)) | F8: =IF($C$3="Conservative",'Scenario Backup'!F5,IF($C$3="Moderate",'Scenario Backup'!F11,'Scenario Backup'!F17)) | G8: =IF($C$3="Conservative",'Scenario Backup'!G5,IF($C$3="Moderate",'Scenario Backup'!G11,'Scenario Backup'!G17))
B9: Effectiveness % | C9: =IF($C$3="Conservative",'Scenario Backup'!C6,IF($C$3="Moderate",'Scenario Backup'!C12,'Scenario Backup'!C18)) | D9: =IF($C$3="Conservative",'Scenario Backup'!D6,IF($C$3="Moderate",'Scenario Backup'!D12,'Scenario Backup'!D18)) | E9: =IF($C$3="Conservative",'Scenario Backup'!E6,IF($C$3="Moderate",'Scenario Backup'!E12,'Scenario Backup'!E18)) | F9: =IF($C$3="Conservative",'Scenario Backup'!F6,IF($C$3="Moderate",'Scenario Backup'!F12,'Scenario Backup'!F18)) | G9: =IF($C$3="Conservative",'Scenario Backup'!G6,IF($C$3="Moderate",'Scenario Backup'!G12,'Scenario Backup'!G18))
B10: YoY Growth % | C10: =IF($C$3="Conservative",'Scenario Backup'!C7,IF($C$3="Moderate",'Scenario Backup'!C13,'Scenario Backup'!C19)) | D10: =IF($C$3="Conservative",'Scenario Backup'!D7,IF($C$3="Moderate",'Scenario Backup'!D13,'Scenario Backup'!D19)) | E10: =IF($C$3="Conservative",'Scenario Backup'!E7,IF($C$3="Moderate",'Scenario Backup'!E13,'Scenario Backup'!E19)) | F10: =IF($C$3="Conservative",'Scenario Backup'!F7,IF($C$3="Moderate",'Scenario Backup'!F13,'Scenario Backup'!F19)) | G10: =IF($C$3="Conservative",'Scenario Backup'!G7,IF($C$3="Moderate",'Scenario Backup'!G13,'Scenario Backup'!G19))
B12: CASH INFLOWS (Benefits)
C13: Year 1 | D13: Year 2 | E13: Year 3 | F13: Year 4 | G13: Year 5 | H13: Total
B14: Digital Customer Onboarding (CASA) | C14: ='Journey Analysis'!$C$18*C$8*C$9*(1+C$10) | D14: ='Journey Analysis'!$C$18*D$8*D$9*(1+D$10) | E14: ='Journey Analysis'!$C$18*E$8*E$9*(1+E$10) | F14: ='Journey Analysis'!$C$18*F$8*F$9*(1+F$10) | G14: ='Journey Analysis'!$C$18*G$8*G$9*(1+G$10) | H14: =SUM(C14:G14)
B15: Loan Origination (Personal & SME) | C15: ='Journey Analysis'!$C$32*C$8*C$9*(1+C$10) | D15: ='Journey Analysis'!$C$32*D$8*D$9*(1+D$10) | E15: ='Journey Analysis'!$C$32*E$8*E$9*(1+E$10) | F15: ='Journey Analysis'!$C$32*F$8*F$9*(1+F$10) | G15: ='Journey Analysis'!$C$32*G$8*G$9*(1+G$10) | H15: =SUM(C15:G15)
B16: Customer Servicing | C16: ='Servicing Analysis'!$H$27*C$8*C$9*(1+C$10) | D16: ='Servicing Analysis'!$H$27*D$8*D$9*(1+D$10) | E16: ='Servicing Analysis'!$H$27*E$8*E$9*(1+E$10) | F16: ='Servicing Analysis'!$H$27*F$8*F$9*(1+F$10) | G16: ='Servicing Analysis'!$H$27*G$8*G$9*(1+G$10) | H16: =SUM(C16:G16)
B17: Total Cash Inflow | C17: =SUM(C14:C16) | D17: =SUM(D14:D16) | E17: =SUM(E14:E16) | F17: =SUM(F14:F16) | G17: =SUM(G14:G16) | H17: =SUM(C17:G17)
B19: CASH OUTFLOWS (Investment)
C20: Year 1 | D20: Year 2 | E20: Year 3 | F20: Year 4 | G20: Year 5 | H20: Total
B21: License | C21: 1200000 | D21: 1500000 | E21: 1500000 | F21: 1500000 | G21: 1500000 | H21: =SUM(C21:G21)
B22: Implementation | C22: 4000000 | D22: 1500000 | E22: 500000 | F22: 500000 | G22: 500000 | H22: =SUM(C22:G22)
B23: Total Cash Outflow | C23: =C21+C22 | D23: =D21+D22 | E23: =E21+E22 | F23: =F21+F22 | G23: =G21+G22 | H23: =SUM(C23:G23)
B25: NET CASHFLOW | C25: =C17-C23 | D25: =D17-D23 | E25: =E17-E23 | F25: =F17-F23 | G25: =G17-G23 | H25: =SUM(C25:G25)
B26: Cumulative Cashflow | C26: =C25 | D26: =C26+D25 | E26: =D26+E25 | F26: =E26+F25 | G26: =F26+G25
B29: FINANCIAL METRICS
B30: Total 5-Year Investment | C30: =H23
B31: Total 5-Year Benefits | C31: =H17
B32: Net Benefit | C32: =C31-C30
B33: ROI | C33: =IF(C30=0,"",C32/C30)
B34: Net Present Value (NPV) | C34: =NPV($C$4,D25:G25)+C25
B35: Internal Rate of Return (IRR) | C35: =IFERROR(IRR(C25:G25),"N/A")
B36: Payback Period (years) | C36: 1.6

Sheet Journey Analysis
B1: Journey Value Analysis
B3: Annual steady-state benefit per journey. Yearly projections on Cashflows sheet.
B6: Digital Customer Onboarding (CASA)
B8: Revenue Generation
B9: Driver | C9: Annual Benefit
B10: Increase Customer Conversion - Digital Channel | C10: 3960000
B11: Revenue Generation Total | C11: =SUM(C10:C10)
B13: Cost Reduction
B14: Driver | C14: Annual Benefit
B15: Reduce Onboarding Processing Cost | C15: 12600000
B16: Cost Reduction Total | C16: =SUM(C15:C15)
B18: Digital Customer Onboarding (CASA) - Total Annual Benefit | C18: =C11+C16
B20: Loan Origination (Personal & SME)
B22: Revenue Generation
B23: Driver | C23: Annual Benefit
B24: Increase Loan Application Conversion | C24: 7200000
B25: Revenue Generation Total | C25: =SUM(C24:C24)
B27: Cost Reduction
B28: Driver | C28: Annual Benefit
B29: Reduce Loan Processing Cost | C29: 2700000
B30: Cost Reduction Total | C30: =SUM(C29:C29)
B32: Loan Origination (Personal & SME) - Total Annual Benefit | C32: =C25+C30

Sheet Servicing Analysis
B1: Customer Servicing - Channel Analysis
B3: Evidence IDs: E5
B4: Baseline = Volume x Time x Rate (formula). Saved = Baseline x Impact (formula).
B6: Task | C6: Volume | D6: Time (hrs) | E6: Rate | F6: Baseline | G6: Impact | H6: Saved | I6: Source
B8: Branch
B9: Balance & Account Inquiry | C9: 150000 | D9: 0.1 | E9: ='Bank Profile'!$C$23 | F9: =C9*D9*E9 | G9: 0.7 | H9: =F9*G9 | I9: ESTIMATE - 30% of customers visit branch annually.
B10: Statement & Document Requests | C10: 100000 | D10: 0.17 | E10: ='Bank Profile'!$C$23 | F10: =C10*D10*E10 | G10: 0.8 | H10: =F10*G10 | I10: ESTIMATE - 20% of customers request statements in branch.
B11: Card Services | C11: 50000 | D11: 0.17 | E11: ='Bank Profile'!$C$23 | F11: =C11*D11*E11 | G11: 0.85 | H11: =F11*G11 | I11: ESTIMATE - Card-related branch visits.
B12: Branch Subtotal | C12: =SUM(C9:C11) | F12: =SUM(F9:F11) | H12: =SUM(H9:H11)
B14: Call Center
B15: Balance & Account Inquiry | C15: 400000 | D15: 0.08 | E15: ='Bank Profile'!$C$23 | F15: =C15*D15*E15 | G15: 0.7 | H15: =F15*G15 | I15: ESTIMATE - High call volume for simple inquiries.
B16: Statement Requests | C16: 200000 | D16: 0.1 | E16: ='Bank Profile'!$C$23 | F16: =C16*D16*E16 | G16: 0.85 | H16: =F16*G16 | I16: ESTIMATE - Frequent call reason.
B17: Card Services | C17: 150000 | D17: 0.12 | E17: ='Bank Profile'!$C$23 | F17: =C17*D17*E17 | G17: 0.9 | H17: =F17*G17 | I17: ESTIMATE - Emergency and routine card calls.
B18: Transaction Inquiries | C18: 300000 | D18: 0.15 | E18: ='Bank Profile'!$C$23 | F18: =C18*D18*E18 | G18: 0.55 | H18: =F18*G18 | I18: ESTIMATE - Common call reason.
B19: Call Center Subtotal | C19: =SUM(C15:C18) | F19: =SUM(F15:F18) | H19: =SUM(H15:H18)
B21: Back Office
B22: Document Processing | C22: 80000 | D22: 0.5 | E22: ='Bank Profile'!$C$23 | F22: =C22*D22*E22 | G22: 0.5 | H22: =F22*G22 | I22: ESTIMATE - Follow-up document handling.
B23: Account Maintenance | C23: 60000 | D23: 0.33 | E23: ='Bank Profile'!$C$23 | F23: =C23*D23*E23 | G23: 0.4 | H23: =F23*G23 | I23: ESTIMATE - Changes requiring back office.
B24: Back Office Subtotal | C24: =SUM(C22:C23) | F24: =SUM(F22:F23) | H24: =SUM(H22:H23)
B27: TOTAL SERVICING | C27: =C12+C19+C24 | F27: =F12+F19+F24 | H27: =H12+H19+H24

Sheet Journey Inputs
B1: Value Driver Inputs by Journey
B3: Color coding: Green=Transcript, Yellow=Estimate, Blue=Benchmark
B5: Basic Information
B6: Input | C6: Value | D6: Conf. | E6: Source
B7: Total Customers | C7: 500000 | D7: LOW | E7: PROVIDED - Client confirmed 500,000 retail customers.
B8: Annual Revenue | C8: 200000000 | D8: LOW | E8: PROVIDED - Client confirmed $200M annual revenue.
B9: Average FTE Rate/Hour | C9: 20 | D9: LOW | E9: ESTIMATE - SEA regional loaded cost. REQUIRES VALIDATION with Finance.
B12: Digital Customer Onboarding (CASA)
B13: Evidence from Discovery:
B14: "Current onboarding takes 5 days - Client Input (E1)"
B15: "Target is same-day digital onboarding - Client Input (E2)"
B17: Revenue Drivers
B18: Increase Customer Conversion - Digital Channel
B19: Monthly Digital Applications | C19: 15000 | D19: MEDIUM | E19: ESTIMATE - Based on 500K customers, 3.6% annual growth implies ~180K new customers/year, 80% start digitally.
B20: Current Abandonment Rate | C20: 0.55 | D20: MEDIUM | E20: ESTIMATE - 5-day process typically sees 50-60% abandonment. Using 55%.
B21: Average First Year Revenue | C21: 400 | D21: HIGH | E21: DERIVED - $200M revenue / 500K customers = $400/customer.
B22: Backbase Impact | C22: 0.1 | D22: MEDIUM | E22: BACKBASE BENCHMARK - Same-day onboarding typically improves conversion by 8-12%.
B23: Potential Annual Benefit | C23: 3960000
B25: Cost Drivers
B26: Reduce Onboarding Processing Cost
B27: Annual Applications | C27: 180000 | D27: MEDIUM | E27: ESTIMATE - 15K monthly applications * 12 months.
B28: Current Processing Hours | C28: 4 | D28: LOW | E28: ESTIMATE - 5-day process implies significant manual work. 4 hours of FTE time per application.
B29: Target Processing Hours | C29: 0.5 | D29: MEDIUM | E29: ESTIMATE - Same-day digital reduces to 30 min review/approval.
B30: Fte Cost Per Hour | C30: 20 | D30: LOW | E30: ESTIMATE - SEA regional loaded cost.
B31: Potential Annual Benefit | C31: 12600000
B34: Loan Origination (Personal & SME)
B35: Evidence from Discovery:
B36: "Want to improve loan origination process - Client Input (E3)"
B37: "Loans tied to digital experience improvements - Client Input (E4)"
B39: Revenue Drivers
B40: Increase Loan Application Conversion
B41: Annual Loan Applications | C41: 75000 | D41: LOW | E41: ESTIMATE - Based on 500K customers, ~15% apply for loans annually.
B42: Current Conversion Rate | C42: 0.4 | D42: LOW | E42: ESTIMATE - Industry average for traditional loan processes is 35-45%.
B43: Average Loan Revenue | C43: 800 | D43: LOW | E43: ESTIMATE - Average interest income + fees per approved loan (Year 1).
B44: Backbase Impact | C44: 0.2 | D44: MEDIUM | E44: BACKBASE BENCHMARK - Digital loan origination improves conversion by 15-25%.
B45: Potential Annual Benefit | C45: 7200000
B47: Cost Drivers
B48: Reduce Loan Processing Cost
B49: Annual Loan Applications | C49: 75000 | D49: LOW | E49: ESTIMATE - Same as revenue driver.
B50: Current Processing Hours | C50: 6 | D50: LOW | E50: ESTIMATE - Traditional loan requires credit check, verification, underwriting.
...

Sheet Scenario Backup
B1: Scenario Definitions
B4: Conservative | C4: Year 1 | D4: Year 2 | E4: Year 3 | F4: Year 4 | G4: Year 5
B5: Implementation % | C5: 0.2 | D5: 0.6 | E5: 0.8 | F5: 0.9 | G5: 1
B6: Effectiveness % | C6: 0.1 | D6: 0.25 | E6: 0.45 | F6: 0.7 | G6: 0.85
B7: YoY Growth % | C7: 0.08 | D7: 0.08 | E7: 0.08 | F7: 0.08 | G7: 0.08
B10: Moderate | C10: Year 1 | D10: Year 2 | E10: Year 3 | F10: Year 4 | G10: Year 5
B11: Implementation % | C11: 0.3 | D11: 0.7 | E11: 0.9 | F11: 1 | G11: 1
B12: Effectiveness % | C12: 0.15 | D12: 0.4 | E12: 0.65 | F12: 0.85 | G12: 1
B13: YoY Growth % | C13: 0.08 | D13: 0.08 | E13: 0.08 | F13: 0.08 | G13: 0.08
B16: Aggressive | C16: Year 1 | D16: Year 2 | E16: Year 3 | F16: Year 4 | G16: Year 5
B17: Implementation % | C17: 0.4 | D17: 0.8 | E17: 0.95 | F17: 1 | G17: 1
B18: Effectiveness % | C18: 0.25 | D18: 0.5 | E18: 0.75 | F18: 0.9 | G18: 1
B19: YoY Growth % | C19: 0.08 | D19: 0.08 | E19: 0.08 | F19: 0.08 | G19: 0.08
B21: Note: Edit curves above to adjust scenario assumptions.

Sheet Assumptions
B1: Assumptions Register
B3: All assumptions documented with sources and validation owners
B5: ID | C5: Assumption | D5: Value | E5: Conf. | F5: Source | G5: Owner | H5: Sensitivity
B6: A1 | C6: Total Customer Base | D6: 500,000 | E6: HIGH | F6: PROVIDED - Client confirmed. | G6: Client | H6: HIGH - Affects all per-customer calculations
B7: A2 | C7: Annual Revenue | D7: $200,000,000 | E7: HIGH | F7: PROVIDED - Client confirmed. | G7: Client | H7: HIGH - Core financial metric
B8: A3 | C8: Cost-to-Income Ratio | D8: 65% | E8: HIGH | F8: PROVIDED - Client confirmed. | G8: Client | H8: MEDIUM - Defines cost structure
B9: A4 | C9: Current Onboarding Time | D9: 5 days | E9: HIGH | F9: PROVIDED - Client confirmed. | G9: Client | H9: HIGH - Core improvement driver
B10: A5 | C10: Target Onboarding Time | D10: Same day | E10: HIGH | F10: PROVIDED - Client confirmed target. | G10: Client | H10: HIGH - Defines benefit potential
B11: A6 | C11: Monthly Digital Applications | D11: 15,000 | E11: MEDIUM | F11: ESTIMATE - Based on customer base and typical growth rates. | G11: Digital Lead | H11: HIGH - Core driver of onboarding benefits
B12: A7 | C12: Digital Abandonment Rate | D12: 55% | E12: MEDIUM | F12: ESTIMATE - 5-day process typically sees 50-60% abandonment. | G12: Digital Lead | H12: HIGH - Defines improvement headroom
B13: A8 | C13: Loaded FTE Cost per Hour | D13: $20 | E13: LOW | F13: ESTIMATE - SEA regional average. | G13: Finance/HR | H13: HIGH - Affects all cost calculations
B14: A9 | C14: Annual Loan Applications | D14: 75,000 | E14: LOW | F14: ESTIMATE - 15% of customers apply for loans annually. | G14: Lending Head | H14: HIGH - Core driver of loan origination benefits
B15: A10 | C15: Implementation Timeline | D15: 30-70-90-100-100% | E15: MEDIUM | F15: BACKBASE BENCHMARK - Accelerated curve for same-day target. | G15: Value Consulting | H15: MEDIUM - Affects timing of benefits

Sheet Bank Profile
B1: Bank Profile
B3: Bank Identity
B4: Field | C4: Value | E4: Source
B5: Bank Name | C5: Southeast Asia Commercial Joint Stock Bank (SeABank)
B6: Country | C6: Vietnam
B7: Currency | C7: VND
B8: Stock Ticker | C8: SSB (Ho Chi Minh Stock Exchange / HoSE)
B9: Report Year | C9: 2024
B10: Report Source | C10: Annual Report 2024 + FY2024 Results Press Release
B12: Key Financial Metrics (Direct)
B13: Metric | C13: Value | D13: Confidence | E13: Source
B14: Total Customers | C14: 3000000 | D14: HIGH | E14: SeABank Best Workplace 2024 — '3M+ customers'
B15: Annual Revenue | C15: 490000000 | D15: HIGH | E15: FY2024 Results — TOI VND 12,409B (~US$490M)
B16: Operating Costs | C16: 163000000 | D16: MEDIUM | E16: DERIVED: TOI $490M x CIR 33.28% = ~$163M
B17: Cost-to-Income Ratio | C17: 0.3328 | D17: HIGH | E17: FY2024 Results — CIR 33.28%
B18: Total FTE | C18: 5500 | D18: HIGH | E18: SeABank Best Workplace 2024 — 'over 5,500 official employees'
B19: Staff Costs (Annual) | C19: 97800000 | D19: LOW | E19: ESTIMATED: OpEx $163M x 60% staff ratio = ~$97.8M (typical for VN banks)
B21: Derived Metrics
B22: Metric | C22: Value | D22: Confidence | E22: Derivation | F22: Formula
B23: Average FTE Rate / Hour | C23: =IFERROR(C19/C18/2000,0) | D23: MEDIUM | E23: Staff Costs / Total FTE / 2,000 working hours | F23: =C19/C18/2000
B24: Average Revenue / Customer | C24: =IFERROR(C15/C14,0) | D24: MEDIUM | E24: Annual Revenue / Total Customers | F24: =C15/C14
B25: Cost per FTE (Annual) | C25: =IFERROR(C19/C18,0) | D25: MEDIUM | E25: Staff Costs / Total FTE | F25: =C19/C18
B26: OpEx per Customer | C26: =IFERROR(C16/C14,0) | D26: MEDIUM | E26: Operating Costs / Total Customers | F26: =C16/C14
B28: Additional Context
B29: Metric | C29: Value | E29: Source
B30: Total Assets | C30: 12850000000 | E30: FY2024 Results — VND 325,699B (~US$12.85B), +22% YoY
B31: Total Loans | C31: 8260000000 | E31: FY2024 Results — Credit outstanding VND 209,355B (~US$8.26B)
B32: Total Deposits | C32: 8520000000 | E32: FY2024 Results — Total mobilization VND 215,984B (~US$8.52B)
B33: Number of Branches | C33: 181 | E33: SeABank Best Workplace 2024 — 181 transaction points nationwide
B34: Digital Active Users | C34: 4000000 | E34: FY2024 Results — Nearly 4M digital users
B35: NPL Ratio | C35: 0.0189 | E35: FY2024 Results — NPL ratio 1.89%
B36: Return on Equity (ROE) | C36: 0.1475 | E36: FY2024 Results — ROE 14.75%
B37: Return on Assets (ROA) | C37: 0.0163 | E37: FY2024 Results — ROA 1.63%
B38: CASA Balance | C38: 1290000000 | E38: FY2024 Results — CASA VND 32,658B (~US$1.29B), +96% YoY
B39: Digital Transactions | C39: 52600000 | E39: FY2024 Results — 52.6M digital transactions, +160% YoY
B40: Charter Capital | C40: 1120000000 | E40: FY2024 Results — Charter capital VND 28,350B (~US$1.12B)
B43: Data Gaps (from Bank Profile)
B44: Metric | C44: Priority | E44: Impact | F44: Where to Obtain
B45: Staff Costs (exact) | C45: HIGH | E45: Required to derive accurate FTE hourly rate — core input for servicing analysis | F45: Annual Report PDF — Income Statement or Notes to Accounts
B46: Net Interest Income | C46: MEDIUM | E46: Revenue composition context — needed for fee income vs interest income split | F46: Annual Report PDF — Income Statement
...

Sheet Data Gaps
B1: Data Gaps - Required for Validation
B3: These data points are CRITICAL for validating the ROI model. Prioritize obtaining this data from the client.
B5: ID | C5: Data Needed | D5: Priority | E5: Source | F5: Impact on Model
B6: DG1 | C6: Actual digital application volume by channel | D6: CRITICAL | E6: Digital analytics / core banking | F6: Core input for onboarding benefit sizing
B7: DG2 | C7: Current onboarding completion/abandonment rate | D7: CRITICAL | E7: Journey analytics / funnel data | F7: Defines improvement headroom
B8: DG3 | C8: Loan application volume and conversion rates | D8: CRITICAL | E8: Lending system / credit operations | F8: Core input for loan origination benefits
B9: DG4 | C9: Processing time per onboarding application | D9: HIGH | E9: Operations / process timing | F9: Sizes processing cost reduction
B10: DG5 | C10: Call center volume by request type | D10: HIGH | E10: Call center reporting system | F10: Core input for servicing cost avoidance
B11: DG6 | C11: Loaded FTE costs by role | D11: HIGH | E11: HR / Finance | F11: Affects all labor cost calculations
B12: DG7 | C12: Current digital adoption rate | D12: MEDIUM | E12: Digital analytics | F12: Defines baseline for channel shift
