Workbook

Sheet Cover Page
B5: Return on Investment Calculator
B7: Value Consulting - Business Case
B10: Client Name: | C10: EMEA Wealth Management Firm
B12: Date: | C12: 2026-02-06
B14: Currency: | C14: USD
B16: Analysis Period: | C16: 5 Years
B18: Selected Scenario: | C18: Moderate
B20: Discount Rate: | C20: 0.08
B24: DATA SOURCE LEGEND
B26: Green | C26: From transcript/client data
B27: Yellow | C27: Estimate - requires validation
B28: Blue | C28: Backbase benchmark
B29: Red border | C29: Low confidence - critical validation

Sheet Instructions
B2: ROI Model Instructions
B5: OVERVIEW
B6: This ROI model calculates value by JOURNEY with LIVE FORMULAS.
B7: All downstream calculations update automatically when inputs change.
B9: HOW FORMULAS WORK
B10: • Blue cells = Editable inputs (change these to update the model)
B11: • White cells with formulas = Calculated automatically
B12: • Change the Scenario on the Cashflows sheet to switch between Conservative/Moderate/Aggressive
B14: JOURNEY-BASED ANALYSIS
B15: • Customer Onboarding - Revenue uplift + Cost reduction from digital onboarding
B16: • Loan Origination - Revenue uplift + Cost reduction from digital lending
B17: • Customer Servicing - Cost avoidance from channel shift (Branch, Call Center, Back Office)
... B40: 5. Review Assumptions sheet with client stakeholders

Sheet Table of Contents
B3: Table of Contents
B5: Section 1 | C5: Results Dashboard
C6: Return on Investment, NPV, IRR
B7: Section 2 | C7: Scenario Backup
C8: Conservative / Moderate / Aggressive curves
B9: Section 3 | C9: Journey Inputs
C10: All inputs with sources and confidence
B11: Section 4 | C11: Journey Analysis
C12: Revenue + Cost benefit calculations (formulas)
B13: Section 5 | C13: Servicing Analysis
C14: Branch / Call Center / Back Office (formulas)
B15: Section 6 | C15: Cash Flows
C16: 5-year projections with scenario switching
B17: Section 7 | C17: Assumptions & Data Gaps
C18: Assumptions Register + Validation Needs

Sheet Results Dashboard
B2: Results Dashboard
B4: Financial Metrics - 5 Year Projections
B5: All values below are live formulas referencing the Cashflows sheet.
B7: Total 5-Year Benefits | C7: =Cashflows!C31
B9: Total 5-Year Investment | C9: =Cashflows!C30
B11: Net Benefit | C11: =Cashflows!C32
B13: ROI | C13: =Cashflows!C33
B15: Net Present Value (NPV) | C15: =Cashflows!C34
B17: Internal Rate of Return (IRR) | C17: =Cashflows!C35
B19: Payback Period (years) | C19: =Cashflows!C36
B22: Benefits by Journey (Annual Steady State)
B24: Journey | C24: Annual Benefit
B25: HNW Client Onboarding | C25: ='Journey Analysis'!C19
B26: Digital Client Engagement | C26: ='Journey Analysis'!C29
B27: Customer Servicing | C27: ='Servicing Analysis'!H29
B28: TOTAL | C28: =SUM(C25:C27)

Sheet Cashflows
B1: 5 Year Cashflows & ROI
B3: Scenario: | C3: Moderate
B4: Discount Rate (WACC): | C4: 0.08
B6: LOADING CURVES (Scenario-Driven)
C7: Year 1 | D7: Year 2 | E7: Year 3 | F7: Year 4 | G7: Year 5
B8: Implementation % | C8: =IF($C$3="Conservative",'Scenario Backup'!C5,IF($C$3="Moderate",'Scenario Backup'!C11,'Scenario Backup'!C17)) | D8: =IF($C$3="Conservative",'Scenario Backup'!D5,IF($C$3="Moderate",'Scenario Backup'!D11,'Scenario Backup'!D17)) | E8: =IF($C$3="Conservative",'Scenario Backup'!E5,IF($C$3="Moderate",'Scenario Backup'!E11,'Scenario Backup'!E17)) | F8: =IF($C$3="Conservative",'Scenario Backup'!F5,IF($C$3="Moderate",'Scenario Backup'!F11,'Scenario Backup'!F17)) | G8: =IF($C$3="Conservative",'Scenario Backup'!G5,IF($C$3="Moderate",'Scenario Backup'!G11,'Scenario Backup'!G17))
B9: Effectiveness % | C9: =IF($C$3="Conservative",'Scenario Backup'!C6,IF($C$3="Moderate",'Scenario Backup'!C12,'Scenario Backup'!C18)) | D9: =IF($C$3="Conservative",'Scenario Backup'!D6,IF($C$3="Moderate",'Scenario Backup'!D12,'Scenario Backup'!D18)) | E9: =IF($C$3="Conservative",'Scenario Backup'!E6,IF($C$3="Moderate",'Scenario Backup'!E12,'Scenario Backup'!E18)) | F9: =IF($C$3="Conservative",'Scenario Backup'!F6,IF($C$3="Moderate",'Scenario Backup'!F12,'Scenario Backup'!F18)) | G9: =IF($C$3="Conservative",'Scenario Backup'!G6,IF($C$3="Moderate",'Scenario Backup'!G12,'Scenario Backup'!G18))
B10: YoY Growth % | C10: =IF($C$3="Conservative",'Scenario Backup'!C7,IF($C$3="Moderate",'Scenario Backup'!C13,'Scenario Backup'!C19)) | D10: =IF($C$3="Conservative",'Scenario Backup'!D7,IF($C$3="Moderate",'Scenario Backup'!D13,'Scenario Backup'!D19)) | E10: =IF($C$3="Conservative",'Scenario Backup'!E7,IF($C$3="Moderate",'Scenario Backup'!E13,'Scenario Backup'!E19)) | F10: =IF($C$3="Conservative",'Scenario Backup'!F7,IF($C$3="Moderate",'Scenario Backup'!F13,'Scenario Backup'!F19)) | G10: =IF($C$3="Conservative",'Scenario Backup'!G7,IF($C$3="Moderate",'Scenario Backup'!G13,'Scenario Backup'!G19))
B12: CASH INFLOWS (Benefits)
C13: Year 1 | D13: Year 2 | E13: Year 3 | F13: Year 4 | G13: Year 5 | H13: Total
B14: HNW Client Onboarding | C14: ='Journey Analysis'!$C$19*C$8*C$9*(1+C$10) | D14: ='Journey Analysis'!$C$19*D$8*D$9*(1+D$10) | E14: ='Journey Analysis'!$C$19*E$8*E$9*(1+E$10) | F14: ='Journey Analysis'!$C$19*F$8*F$9*(1+F$10) | G14: ='Journey Analysis'!$C$19*G$8*G$9*(1+G$10) | H14: =SUM(C14:G14)
B15: Digital Client Engagement | C15: ='Journey Analysis'!$C$29*C$8*C$9*(1+C$10) | D15: ='Journey Analysis'!$C$29*D$8*D$9*(1+D$10) | E15: ='Journey Analysis'!$C$29*E$8*E$9*(1+E$10) | F15: ='Journey Analysis'!$C$29*F$8*F$9*(1+F$10) | G15: ='Journey Analysis'!$C$29*G$8*G$9*(1+G$10) | H15: =SUM(C15:G15)
B16: Customer Servicing | C16: ='Servicing Analysis'!$H$29*C$8*C$9*(1+C$10) | D16: ='Servicing Analysis'!$H$29*D$8*D$9*(1+D$10) | E16: ='Servicing Analysis'!$H$29*E$8*E$9*(1+E$10) | F16: ='Servicing Analysis'!$H$29*F$8*F$9*(1+F$10) | G16: ='Servicing Analysis'!$H$29*G$8*G$9*(1+G$10) | H16: =SUM(C16:G16)
B17: Total Cash Inflow | C17: =SUM(C14:C16) | D17: =SUM(D14:D16) | E17: =SUM(E14:E16) | F17: =SUM(F14:F16) | G17: =SUM(G14:G16) | H17: =SUM(C17:G17)
B19: CASH OUTFLOWS (Investment)
C20: Year 1 | D20: Year 2 | E20: Year 3 | F20: Year 4 | G20: Year 5 | H20: Total
B21: License | C21: 1500000 | D21: 2000000 | E21: 2000000 | F21: 2000000 | G21: 2000000 | H21: =SUM(C21:G21)
B22: Implementation | C22: 3500000 | D22: 1500000 | E22: 500000 | F22: 250000 | G22: 250000 | H22: =SUM(C22:G22)
B23: Total Cash Outflow | C23: =C21+C22 | D23: =D21+D22 | E23: =E21+E22 | F23: =F21+F22 | G23: =G21+G22 | H23: =SUM(C23:G23)
B25: NET CASHFLOW | C25: =C17-C23 | D25: =D17-D23 | E25: =E17-E23 | F25: =F17-F23 | G25: =G17-G23 | H25: =SUM(C25:G25)
B26: Cumulative Cashflow | C26: =C25 | D26: =C26+D25 | E26: =D26+E25 | F26: =E26+F25 | G26: =F26+G25
B29: FINANCIAL METRICS
B30: Total 5-Year Investment | C30: =H23
B31: Total 5-Year Benefits | C31: =H17
B32: Net Benefit | C32: =C31-C30
B33: ROI | C33: =IF(C30=0,"",C32/C30)
B34: Net Present Value (NPV) | C34: =NPV($C$4,D25:G25)+C25
B35: Internal Rate of Return (IRR) | C35: =IFERROR(IRR(C25:G25),"N/A")
B36: Payback Period (years) | C36: 4.6

Sheet Journey Analysis
B1: Journey Value Analysis
B3: Annual steady-state benefit per journey. Yearly projections on Cashflows sheet.
B6: HNW Client Onboarding
B8: Revenue Generation
B9: Driver | C9: Annual Benefit
B10: Accelerate Time-to-Revenue for New Clients | C10: 461538
B11: Recover Abandoning Prospects | C11: 621000
B12: Revenue Generation Total | C12: =SUM(C10:C11)
B14: Cost Reduction
B15: Driver | C15: Annual Benefit
B16: Reduce Onboarding Processing Cost | C16: 576000
B17: Cost Reduction Total | C17: =SUM(C16:C16)
B19: HNW Client Onboarding - Total Annual Benefit | C19: =C12+C17
B21: Digital Client Engagement
B23: Revenue Generation
B24: Driver | C24: Annual Benefit
B25: Improved Client Retention Through Digital Engagement | C25: 1800000
B26: Digital Cross-Sell and Share of Wallet | C26: 1200000
B27: Revenue Generation Total | C27: =SUM(C25:C26)
B29: Digital Client Engagement - Total Annual Benefit | C29: =C27

Sheet Servicing Analysis
B1: Customer Servicing - Channel Analysis
B3: Evidence IDs: W5, W6
B4: Baseline = Volume x Time x Rate (formula). Saved = Baseline x Impact (formula).
B6: Task | C6: Volume | D6: Time (hrs) | E6: Rate | F6: Baseline | G6: Impact | H6: Saved | I6: Source
B8: Portfolio Reporting
B9: Client Performance Reports | C9: 32000 | D9: 0.75 | E9: 60 | F9: =C9*D9*E9 | G9: 0.6 | H9: =F9*G9 | I9: DERIVED - 8,000 clients x 4 quarterly reports = 32,000 reports/year.
B10: Ad-Hoc Client Reports | C10: 5000 | D10: 0.5 | E10: 60 | F10: =C10*D10*E10 | G10: 0.5 | H10: =F10*G10 | I10: ESTIMATE - ~625 RMs requests per year across 50 RMs.
B11: Investment Analysis & Proposals | C11: 2500 | D11: 1.5 | E11: 60 | F11: =C11*D11*E11 | G11: 0.3 | H11: =F11*G11 | I11: ESTIMATE - ~50 per RM per year.
B12: Portfolio Reporting Subtotal | C12: =SUM(C9:C11) | F12: =SUM(F9:F11) | H12: =SUM(H9:H11)
B14: Client Communications
B15: Portfolio Inquiries (calls/emails) | C15: 18000 | D15: 0.25 | E15: 60 | F15: =C15*D15*E15 | G15: 0.7 | H15: =F15*G15 | I15: ESTIMATE - Avg 2.25 inquiries per client per year.
B16: Transaction & Trade Requests | C16: 14000 | D16: 0.33 | E16: 60 | F16: =C16*D16*E16 | G16: 0.4 | H16: =F16*G16 | I16: ESTIMATE - ~1.75 trade-related requests per client per year.
B17: Document Requests & Sharing | C17: 8000 | D17: 0.17 | E17: 60 | F17: =C17*D17*E17 | G17: 0.8 | H17: =F17*G17 | I17: ESTIMATE - 1 document request per client per year.
B18: Meeting Preparation & Follow-Up | C18: 8000 | D18: 0.5 | E18: 60 | F18: =C18*D18*E18 | G18: 0.35 | H18: =F18*G18 | I18: ESTIMATE - 1 annual review meeting per client.
B19: Client Communications Subtotal | C19: =SUM(C15:C18) | F19: =SUM(F15:F18) | H19: =SUM(H15:H18)
B21: Operations & Compliance
B22: Periodic KYC/AML Reviews | C22: 4000 | D22: 1.5 | E22: 60 | F22: =C22*D22*E22 | G22: 0.4 | H22: =F22*G22 | I22: ESTIMATE - 50% of clients reviewed annually (risk-based).
B23: Account Maintenance & Updates | C23: 4000 | D23: 0.5 | E23: 60 | F23: =C23*D23*E23 | G23: 0.5 | H23: =F23*G23 | I23: ESTIMATE - Address changes, beneficiary updates, mandate changes.
B24: Regulatory & Compliance Documentation | C24: 3000 | D24: 1 | E24: 60 | F24: =C24*D24*E24 | G24: 0.35 | H24: =F24*G24 | I24: ESTIMATE - Suitability reports, best-execution records, MiFID compliance.
B25: Data Entry & Reconciliation | C25: 6000 | D25: 0.75 | E25: 60 | F25: =C25*D25*E25 | G25: 0.55 | H25: =F25*G25 | I25: ESTIMATE - CRM updates, portfolio system entries, manual reconciliations.
B26: Operations & Compliance Subtotal | C26: =SUM(C22:C25) | F26: =SUM(F22:F25) | H26: =SUM(H22:H25)
B29: TOTAL SERVICING | C29: =C12+C19+C26 | F29: =F12+F19+F26 | H29: =H12+H19+H26

Sheet Journey Inputs
B1: Value Driver Inputs by Journey
B3: Color coding: Green=Transcript, Yellow=Estimate, Blue=Benchmark
B5: Basic Information
B6: Input | C6: Value | D6: Conf. | E6: Source
B7: Total Customers | C7: 8000 | D7: LOW | E7: PROVIDED - 8,000 HNW clients confirmed by client.
B8: Annual Revenue | C8: 120000000 | D8: LOW | E8: DERIVED - 8,000 clients x $15,000 revenue/client = $120M.
B9: Average FTE Rate/Hour | C9: 60 | D9: LOW | E9: DERIVED - RM cost $120K/year / 2,000 working hours = $60/hr. Used as primary rate since RM admin reduction is core value driver.
B12: HNW Client Onboarding
B13: Evidence from Discovery:
B14: "Current onboarding takes 3 weeks end-to-end — Client Input (W1)"
B15: "We lose prospects during the lengthy process — Client Input (W2)"
B17: Revenue Drivers
B18: Accelerate Time-to-Revenue for New Clients
B19: New Clients Per Year | C19: 800 | D19: MEDIUM | E19: ESTIMATE - 10% annual growth on 8,000 client base.
B20: Average Client Aum | C20: 1500000 | D20: HIGH | E20: DERIVED - $12B AUM / 8,000 clients = $1.5M average.
B21: Annual Fee Rate | C21: 0.01 | D21: HIGH | E21: DERIVED - $15,000 revenue / $1.5M AUM = 1.0% blended fee rate.
B22: Weeks Saved | C22: 2 | D22: MEDIUM | E22: TARGET - From 3 weeks to 1 week onboarding.
B23: Potential Annual Benefit | C23: 461538
B24: Recover Abandoning Prospects
B25: Annual Prospects | C25: 920 | D25: LOW | E25: ESTIMATE - 800 net new clients implies ~920 initial prospects (15% abandonment).
B26: Current Abandonment Rate | C26: 0.15 | D26: LOW | E26: ESTIMATE - 15% drop-off during 3-week onboarding for HNW segment.
B27: Backbase Recovery Rate | C27: 0.3 | D27: MEDIUM | E27: BACKBASE BENCHMARK - Digital onboarding recovers 25-35% of abandoning prospects.
B28: Revenue Per Client | C28: 15000 | D28: HIGH | E28: PROVIDED - $15,000 annual revenue per HNW client.
B29: Potential Annual Benefit | C29: 621000
B31: Cost Drivers
B32: Reduce Onboarding Processing Cost
B33: Annual New Clients | C33: 800 | D33: MEDIUM | E33: Same as revenue driver.
B34: Current Processing Hours | C34: 20 | D34: LOW | E34: ESTIMATE - 3-week process: KYC checks (6h), document collection (4h), suitability review (3h), account setup (4h), portfolio transfer (3h).
B35: Target Processing Hours | C35: 8 | D35: LOW | E35: ESTIMATE - Digital-first: e-KYC (2h), digital doc upload (1h), automated suitability (1h), system setup (2h), portfolio transfer (2h).
B36: Fte Cost Per Hour | C36: 60 | D36: HIGH | E36: DERIVED - RM cost $120K/year / 2,000 hours = $60/hr.
B37: Potential Annual Benefit | C37: 576000
B40: Digital Client Engagement
B41: Evidence from Discovery:
B42: "Our digital offering is poor — clients call RMs for basic portfolio questions — Client Input (W3)"
B43: "We need to improve digital engagement to retain next-gen wealth clients — Client Input (W4)"
B45: Revenue Drivers
B46: Improved Client Retention Through Digital Engagement
B47: Total Clients | C47: 8000 | D47: HIGH | E47: PROVIDED - 8,000 HNW clients.
B48: Current Annual Churn | C48: 0.05 | D48: LOW | E48: ESTIMATE - 5% annual attrition is typical for HNW segment without strong digital offering.
B49: Churn Reduction | C49: 0.015 | D49: MEDIUM | E49: BACKBASE BENCHMARK - Digital engagement reduces churn by 1-2 percentage points.
...

Sheet Scenario Backup
B1: Scenario Definitions
B4: Conservative | C4: Year 1 | D4: Year 2 | E4: Year 3 | F4: Year 4 | G4: Year 5
B5: Implementation % | C5: 0.15 | D5: 0.45 | E5: 0.7 | F5: 0.9 | G5: 1
B6: Effectiveness % | C6: 0.05 | D6: 0.2 | E6: 0.4 | F6: 0.65 | G6: 0.8
B7: YoY Growth % | C7: 0.05 | D7: 0.05 | E7: 0.05 | F7: 0.05 | G7: 0.05
B10: Moderate | C10: Year 1 | D10: Year 2 | E10: Year 3 | F10: Year 4 | G10: Year 5
B11: Implementation % | C11: 0.25 | D11: 0.6 | E11: 0.85 | F11: 1 | G11: 1
B12: Effectiveness % | C12: 0.1 | D12: 0.35 | E12: 0.6 | F12: 0.8 | G12: 1
B13: YoY Growth % | C13: 0.05 | D13: 0.05 | E13: 0.05 | F13: 0.05 | G13: 0.05
B16: Aggressive | C16: Year 1 | D16: Year 2 | E16: Year 3 | F16: Year 4 | G16: Year 5
B17: Implementation % | C17: 0.35 | D17: 0.75 | E17: 0.95 | F17: 1 | G17: 1
B18: Effectiveness % | C18: 0.2 | D18: 0.5 | E18: 0.75 | F18: 0.9 | G18: 1
B19: YoY Growth % | C19: 0.05 | D19: 0.05 | E19: 0.05 | F19: 0.05 | G19: 0.05
B21: Note: Edit curves above to adjust scenario assumptions.

Sheet Assumptions
B1: Assumptions Register
B3: All assumptions documented with sources and validation owners
B5: ID | C5: Assumption | D5: Value | E5: Conf. | F5: Source | G5: Owner | H5: Sensitivity
B6: W-A1 | C6: HNW Client Base | D6: 8,000 clients | E6: HIGH | F6: PROVIDED - Client confirmed. | G6: Client | H6: HIGH - Affects all per-client calculations
B7: W-A2 | C7: Assets Under Management | D7: $12,000,000,000 | E7: HIGH | F7: PROVIDED - Client confirmed $12B AUM. | G7: Client | H7: HIGH - Determines average AUM per client and fee income
B8: W-A3 | C8: Revenue per Client | D8: $15,000/year | E8: HIGH | F8: PROVIDED - Client confirmed. | G8: Finance | H8: HIGH - Core financial metric for retention and cross-sell benefits
B9: W-A4 | C9: Number of Relationship Managers | D9: 50 RMs | E9: HIGH | F9: PROVIDED - Client confirmed. | G9: Client | H9: HIGH - Defines total admin hours available for reduction
B10: W-A5 | C10: RM Fully Loaded Cost | D10: $120,000/year ($60/hr) | E10: HIGH | F10: PROVIDED - Client confirmed $120K/year per RM. | G10: Finance/HR | H10: HIGH - Affects all servicing cost calculations
B11: W-A6 | C11: Current Admin Time Ratio | D11: 60% of RM time | E11: HIGH | F11: PROVIDED - Client confirmed RMs spend 60% on admin. | G11: Client | H11: HIGH - Defines baseline for admin reduction
B12: W-A7 | C12: Target Admin Time Ratio | D12: 30% of RM time | E12: HIGH | F12: PROVIDED - Client target. | G12: Client | H12: HIGH - Defines benefit ceiling for admin reduction
B13: W-A8 | C13: Current Onboarding Cycle | D13: 3 weeks | E13: HIGH | F13: PROVIDED - Client confirmed 3-week onboarding. | G13: Operations | H13: HIGH - Core driver of onboarding time-to-revenue benefit
B14: W-A9 | C14: Annual Client Churn Rate | D14: 5% | E14: LOW | F14: ESTIMATE - Typical HNW churn without strong digital offering. REQUIRES VALIDATION. | G14: Head of Client Services | H14: HIGH - Core driver of retention benefit
B15: W-A10 | C15: New Client Acquisition Rate | D15: 800/year (10% growth) | E15: LOW | F15: ESTIMATE - Based on typical HNW growth rates. | G15: Head of Client Acquisition | H15: MEDIUM - Affects onboarding benefit sizing
B16: W-A11 | C16: Blended Fee Rate on AUM | D16: 1.0% | E16: HIGH | F16: DERIVED - $15,000 revenue / $1.5M average AUM. | G16: Finance | H16: MEDIUM - Affects time-to-revenue calculation
... B18: W-A13 | C18: Implementation Timeline | D18: 25-60-85-100-100% | E18: MEDIUM | F18: BACKBASE BENCHMARK - Wealth management adoption curve, slower than retail. | G18: Value Consulting | H18: MEDIUM - Affects timing of benefit realization

Sheet Data Gaps
B1: Data Gaps - Required for Validation
B3: These data points are CRITICAL for validating the ROI model. Prioritize obtaining this data from the client.
B5: ID | C5: Data Needed | D5: Priority | E5: Source | F5: Impact on Model
B6: WDG1 | C6: Actual client attrition rate and reasons | D6: CRITICAL | E6: CRM / Client Services reporting | F6: Core input for retention benefit — currently estimated at 5%
B7: WDG2 | C7: RM time allocation breakdown by activity | D7: CRITICAL | E7: RM time study or CRM activity logs | F7: Validates the 60% admin baseline and sizes each servicing task correctly
B8: WDG3 | C8: Client onboarding funnel data (prospects, drop-offs, completion rate) | D8: HIGH | E8: CRM / onboarding system | F8: Sizes the prospect recovery benefit — abandonment rate currently estimated
B9: WDG4 | C9: Actual onboarding processing hours per client | D9: HIGH | E9: Operations team / process timing study | F9: Sizes onboarding cost reduction — currently estimated at 20 hours
B10: WDG5 | C10: Report generation volume and time per report by type | D10: HIGH | E10: Portfolio management team / reporting system logs | F10: Core input for portfolio reporting automation benefit
B11: WDG6 | C11: Client inquiry volume by channel (calls, emails, portal) | D11: HIGH | E11: CRM / telephony system | F11: Validates client communications servicing volumes
B12: WDG7 | C12: Current digital adoption rate among HNW clients | D12: MEDIUM | E12: Digital analytics / client portal usage data | F12: Defines baseline for digital engagement improvement
B13: WDG8 | C13: Cross-sell success rate and incremental revenue per product | D13: MEDIUM | E13: Product management / CRM | F13: Validates cross-sell benefit — currently estimated
B14: WDG9 | C14: Compliance and KYC review frequency and effort per client | D14: MEDIUM | E14: Compliance team | F14: Validates operations & compliance servicing volumes
