Workbook
Name xrate: #REF!

Sheet Cover Page
C13: Return on Investment Calculator
C16: Client Name: | D16: Seabank
C18: Date: | D18: 45809
C21: Value Consulting - Business Case

Sheet Instructions
B1: Return on Investment Instructions
C3: Overview: | D3: This tool will be used to derive the Return on investment (ROI) for purchasing and implementing Backbase as a solution for the bank. Backbase value consulting team will use this ROI calculation tool to develop a business case for a given engagement.
C4: Purpose: | D4: ROI is a performance measure used to evaluate the efficiency and profitability of an investment through directly measuring the amount of return on a particular investment. In other words ROI shows how well an investment has performed, relative to the cost of it. We have developed this model to standardize the approach for calculating ROI and reducing efforts due to the interlinked functionalities between sheets, therefore, users will spend less time building the necessary analysis, rather inputs would be inserted in given cells and the sheet will automatically calculate the final ROI.
C5: Who should use this tool | D5: This tool is expected to be filled and used by value consulting team members
C6: Cell Instructions and Legends | D6: The ROI tool is designed to help end users calculate the return on investment for implementing backbase as a solution. This model aims save time and effort while calculating the final ROI for a potential opportunity. The way to use the this model is explained below: The sheet structure is of two main categories "Inputs" and "Analysis". In the inputs sections, it is expected to be manually filled in order to populate the analysis. Hence, the Analysis sections is automatically populated. Inputs are often gathered during or after a workshop session, however, some inputs follow an assumption based approach. In the "Inputs" section, there will be three legends introduced in order to differentiate between types of inputs as follows: A- "Required information" this field is information given by the customer during or after conducting the workshop session. B- "Calculated Information" this field is automatically generated through a specific formula. D- "Assumption" this field will be assumed by the user based on best practice experience.
C7: Sheet Instructions | D7: Input Sheet | E7: First section in "input" sheet will cover information about the customer such as name, revenue and industry. Second section in "input" sheet covers Backbase loading and effectiveness on customer value drivers, loyalty, retention, and customer servicing. The inputs in this section are based on educated assumptions that should be backed by a sane market study and previous engagements. Third section in "input" sheet covers inputs and assumptions pertaining to potential cost reduction due to digital implementation (reduction in physical channel visits) and revenue generation (through customer conversion, loyalty, and retention). For this section to be filled, workshops have to be conducted with the client in order to derive the needed information.
D8: Cost Reduction and Revenue Generation Sheet | E8: In this section, a detailed analysis of all inputs from the previous section "Input" sheet will be displayed. This sheet will provide a breakdown view of the following details: - Value drivers behind cost reduction in customer acquisition, loan origination, and customer servicing - Value drivers behind revenue generation in customer acquisition and loan origination. Note: this sheet will be automatically generated.
D9: Servicing-Subsection Sheet | E9: This sheet will provide a breakdown view of customer servicing details. According to customer inputs and best practices, the type of services will be displayed in a list under 3 journeys: - Branch - Call Center - Back-office Note: this sheet will be automatically generated.
D10: Cash Flows Sheet | E10: In the "Cash Flows" section a final calculation of cash flows "cash inflows and cash outflows" followed by Payback period, Net present Value, Return on Investment, and Internal Rate of Return will presented. Note: this sheet will automatically generate the aforementioned outputs based on all the inputs from "input" sheet.

Sheet Table of Contents
B3: Table of Contents
B5: Section 1 | C5: Results Dashboard
C6: Return on Investment
C7: Net Present Value
C8: Payback Period
B9: Section 2 | C9: Value Driver Inputs
C10: Customer Onboarding
C11: Loan Origination
C12: Loyalty and Retention
C13: Servicing Inputs
B14: Section 3 | C14: Value Driver Analysis
C15: Customer Onboarding
C16: Loan Origination
C17: Loyalty and Retention
B18: Section 4 | C18: Servicing Analysis
C19: Branch
C20: Call Center
C21: Back Office
C22: Impact on Customer Onboarding
B23: Section 5 | C23: IT Cost Savings - Estimation & Analysis
C24: Impact on Loan Origination
C25: Impact on Loyalty and Retention
C26: Impact on Customer Servicing
B27: Section 6 | C27: Cash Flows
C28: Projection Inflows
C29: Projection Outflows
C30: Return on Investment
C31: Net Present Value
C32: Payback Period

Sheet Results Dashboard
B2: Financial Metrics 5 Year Projections
E5: Revenues | R5: Costs
B6: Return on Investment (ROI)
B7: ='Cashflows - Analysis'!N14 -> 29274570
B12: Net Present Value (NPV)
B13: ='Cashflows - Analysis'!N13 -> 4054730.8
B17: Internal Rate of Return (IRR)
B18: ='Cashflows - Analysis'!N21 -> 0.45666217
B24: Payback Period in Years
B25: ='Cashflows - Analysis'!N20 -> 1.7279603

Sheet Customer Phases - Inputs and As
B2: Backbase VC - Business Case
B3: Customer Phases - Inputs and Assumptions
C5: Required info
C6: Calculation
C7: Assumptions / Backbase benchmarks | F7: CCurr
B11: Basic Information
B12: Initial Data
B13: Customer Name | C13: Seabank | E13: Ave. revenue / customer | F13: 39.87 | H13: Product Penetration | I13: 2.53
B14: Industry | C14: Banking | E14: Average FTE rate/ hour | F14: =(I14/F16)/(250*8) -> 8.0103948 | H14: Total Staff Costs | I14: ='Annual report data'!J23 -> 84349457
B15: Revenue 2024 | C15: ='Annual report data'!E11 -> 11078105 | E15: Total customers | F15: 3656262
B16: currency conversion rate (VND to USD) | C16: =1/'Annual report data'!E7 -> 3.99106e-05 | E16: Total FTE | F16: 5265
B19: Backbase Loading and Effectiveness on Customer/Loan Acquisition | I19: Backbase Loading and Effectiveness on Customer Servicing
C20: Year 1 | D20: Year 2 | E20: Year 3 | F20: Year 4 | G20: Year 5 | J20: Year 1 | K20: Year 2 | L20: Year 3 | M20: Year 4 | N20: Year 5
B21: Backbase Implementation | C21: 0.3 | D21: 0.7 | E21: 0.8 | F21: 1 | G21: 1 | I21: Backbase Implementation | J21: 0.3 | K21: 0.7 | L21: 0.8 | M21: 1 | N21: 1
B22: Backbase Effectiveness (Adoption Rate) | C22: 0.15 | D22: 0.35 | E22: 0.6 | F22: 0.85 | G22: 1 | I22: Backbase Effectiveness (Adoption Rate) | J22: 0.15 | K22: 0.35 | L22: 0.6 | M22: 0.85 | N22: 1
B23: Year on Year Growth | C23: 0.15 | D23: 0.15 | E23: 0.15 | F23: 0.15 | G23: 0.15 | I23: Year on Year Growth | J23: 0.08 | K23: 0.08 | L23: 0.08 | M23: 0.08 | N23: 0.08
B25: Backbase Loading and Effectiveness on Customer Churn | I25: Backbase Loading and Effectiveness on Product Penetration
C26: Year 1 | D26: Year 2 | E26: Year 3 | F26: Year 4 | G26: Year 5 | J26: Year 1 | K26: Year 2 | L26: Year 3 | M26: Year 4 | N26: Year 5
B27: Backbase Implementation | C27: 0.3 | D27: 0.7 | E27: 0.8 | F27: 1 | G27: 1 | I27: Backbase Implementation | J27: 0.3 | K27: 0.7 | L27: 0.8 | M27: 1 | N27: 1
B28: Backbase Effectiveness (Adoption Rate) | C28: 0.15 | D28: 0.35 | E28: 0.6 | F28: 0.85 | G28: 1 | I28: Backbase Effectiveness (Adoption Rate) | J28: 0.15 | K28: 0.35 | L28: 0.6 | M28: 0.85 | N28: 1
B29: Year on Year Growth | C29: 0.1 | D29: 0.1 | E29: 0.1 | F29: 0.1 | G29: 0.1 | I29: Year on Year Growth | J29: 0.08 | K29: 0.08 | L29: 0.08 | M29: 0.08 | N29: 0.08
W30: total CCs | X30: 273000
B33: Customer Onboarding (CASA) | E33: USL Loan Acquisition | H33: Loyalty & Retention | K33: CLO | N33: Servicing Journey Names: Retail and SME
B35: Increase Customer Conversion in website | E35: Increase Customer Conversion in website | H35: Improve Customer Churn | K35: Activation / Dormancy Reduction | N35: Branch | Q35: Call Center | S35: Back-Office | U35: Impact
B36: Customers that start onboarding | C36: =153108+361339 -> 514447 | D36: From Sebank: Android: 153,108 IOS: 361,339 | E36: Intent to Purchase Lending Product (personal loans) | F36: =F74*3 -> 24129 | G36: Assumption: 3x total new customers | H36: Total number of current active customers | I36: =F15*12% -> 438751.44 | J36: Seabank data | K36: Total Number of New Customers | L36: =C73 -> 609377 | N36: Service | O36: Volume | P36: Time Spent in HR | Q36: Volume | R36: Time Spent in HR | S36: Volume | T36: Time Spent in HR | U36: Backbase Impact | V36: Notes | W36: Assumption: Volumes in branch taken for comparable VN bank; capped at 70% accounting for difference in # of branches and customer base | Y36: Assumption: 5x of actual customers ordered CC online
B37: Current Customer Leakage (%) - includes Activation leakage | C37: =1-((65699+52075)/C36) -> 0.7710668 | D37: Data from Seabank: Q4/2024: 52,075 user 2025: 65,699 user | E37: Current Customer Leakage (%) | F37: =1-(F74/F36) -> 0.66666667 | H37: Customer Churn | I37: 0.02 | J37: Seabank data | K37: Current Activation Rate | L37: =18% -> 0.18 | M37: From SeABank | N37: Accounts & Balance | O37: =150241*70% -> 105168.7 | P37: 0.08 | Q37: =1560*12 -> 18720 | R37: ='Extra Tables Parking lot'!F15 -> 0.083333333 | S37: ='Extra Tables Parking lot'!G15 -> 0 | T37: ='Extra Tables Parking lot'!H15 -> 0 | U37: 0.35 | V37: Volumes in branch assumed for lack of accurate data from Seabank | W37: =O37/$O$55 -> 0.1306192 | X37: =Q37/$Q$55 -> 0.22306959
B38: Average Income per Customer | C38: =F13 -> 39.87 | D38: From seabank | E38: Average Income per Customer | F38: =F13 -> 39.87 | H38: Average Income per Customer | I38: =F13 -> 39.87 | K38: Number of inactive customers | L38: =L36*(1-L37) -> 499689.14 | N38: Account Statement | O38: =107315*70% -> 75120.5 | P38: 0.17 | R38: ='Extra Tables Parking lot'!F16 -> 0.16666667 | S38: ='Extra Tables Parking lot'!G16 | T38: ='Extra Tables Parking lot'!H16 | U38: 0.4 | V38: Volumes in branch assumed for lack of accurate data from Seabank | W38: =O38/$O$55 -> 0.093299427 | X38: =Q38/$Q$55 -> 0
B39: Backbase Impact | C39: =10%*75% -> 0.075 | D39: Assumption: Integrated digital onboarding solution (with A/C funding will remove friction in the onboarding process across branch/digital channels) | E39: Backbase Impact | F39: =20%*75% -> 0.15 | H39: Backbase Impact | I39: =10%*75% -> 0.075 | K39: Backbase Impact | L39: 0.15 | N39: Transaction Dispute | O39: =76839*70% -> 53787.3 | P39: 0.33 | Q39: =400*12 -> 4800 | R39: ='Extra Tables Parking lot'!F17 -> 0.25 | T39: ='Extra Tables Parking lot'!H17 -> 0.75 | U39: 0.4 | V39: Volumes in branch assumed for lack of accurate data from Seabank | W39: =O39/$O$55 -> 0.066803659 | X39: =Q39/$Q$55 -> 0.057197331
N40: Transfers | O40: =148653*(12/5) -> 356767.2 | P40: =10/60 -> 0.16666667 | Q40: =940*12 -> 11280 | R40: ='Extra Tables Parking lot'!F18 -> 0.083333333 | S40: ='Extra Tables Parking lot'!G18 -> 0 | T40: ='Extra Tables Parking lot'!H18 -> 0 | U40: 0.1 | V40: Data from seabank | W40: =O40/$O$55 -> 0.44310375
B41: Increase Customer Conversion in Direct (Branch) Sales - Branch onboarding | E41: Increase Customer Conversion in Direct (Branch) Sales. Branch Lending Origination | H41: Increase Product Penetration | K41: Product Cross / Upsell | N41: internal transfers | Q41: ='Extra Tables Parking lot'!E19 -> 0 | R41: ='Extra Tables Parking lot'!F19 -> 0.16666667 | S41: ='Extra Tables Parking lot'!G19 -> 0 | T41: ='Extra Tables Parking lot'!H19 -> 0.083333333 | U41: 0.1 | W41: =O41/$O$55 -> 0 | X41: =Q41/$Q$55 -> 0
B42: No of Visits/Year | C42: =(193177/80%) -> 241471.25 | D42: Of 193K accounts opened in branch, there is 20% leakage i.e., 5-10% customers who failed to open because they did not like the process and 5-10% that inquired but were not interested in a product | E42: No of Visits/Year | F42: =(F73-F74)*2 -> 103600 | G42: Assumption: 2x new loans | H42: Total number of current customers | I42: =F15 -> 3656262 | K42: Total Customer Base | L42: =F15 -> 3656262 | N42: Debit Card Ordering | O42: =3162*(12/5) -> 7588.8 | P42: =15/60 -> 0.25 | Q42: =90*12 -> 1080 | R42: ='Extra Tables Parking lot'!F20 -> 0.16666667 | T42: ='Extra Tables Parking lot'!H20 -> 0.5 | U42: 0.35 | V42: Data from seabank | W42: =O42/$O$55 -> 0.0094252659 | X42: =Q42/$Q$55 -> 0.012869399
B43: Current Customer Leakage (%) - Activation leakage | C43: 0.2 | D43: Assumption | E43: Current Customer Leakage (%) | F43: =(F73-F74)/F42 -> 0.5 | H43: Digital Inactive Customers | I43: =F15-I36 -> 3217510.6 | K43: of which, already purchase 2nd product | L43: =18% -> 0.18 | M43: Assumption, 18% of active base would already buy the second product | N43: Card block | O43: =1638*70% -> 1146.6 | P43: 0.17 | Q43: =440*12 -> 5280 | R43: ='Extra Tables Parking lot'!F21 -> 0.083333333 | S43: ='Extra Tables Parking lot'!G21 -> 0 | T43: ='Extra Tables Parking lot'!H21 -> 0 | U43: 0.2 | V43: Volumes in branch assumed for lack of accurate data from Seabank | W43: =O43/$O$55 -> 0.0014240736 | X43: =Q43/$Q$55 -> 0.062917064 | Y43: Customers who were rejected or dropped out of the process
B44: Average Income per Customer | C44: =F13 -> 39.87 | E44: Average Income per Customer | F44: =F38 -> 39.87 | H44: Average Income per Additional Product | I44: =($C$38*(9/10)+$F$38*(1/10))/2 -> 19.935 | J44: Assumption: for every 10 deposit products sold, 1 loan product is sold | K44: Income per additional product | L44: =I44 -> 19.935 | M44: Assumption: for every 10 deposit products sold, 1 loan product is sold | N44: Cards PIN reset | O44: =1092*70% -> 764.4 | P44: 0.17 | Q44: =120*12 -> 1440 | R44: ='Extra Tables Parking lot'!F22 -> 0.083333333 | S44: ='Extra Tables Parking lot'!G22 -> 0 | T44: ='Extra Tables Parking lot'!H22 -> 0 | U44: 0.2 | V44: Volumes in branch assumed for lack of accurate data from Seabank | W44: =O44/$O$55 -> 0.00094938242 | X44: =Q44/$Q$55 -> 0.017159199
B45: Backbase Impact | C45: =10%*75% -> 0.075 | D45: Assumption: Due to better CX , 5% customers activate | E45: Backbase Impact | F45: =10%*75% -> 0.075 | G45: Based on backbase impact in increasing origination at comparable banks; global average | H45: Backbase Impact | I45: =5%*75% -> 0.0375 | J45: Bundled products during onboarding | K45: Backbase Impact | L45: 0.05 | M45: Impact assumption: 0.3-0.5 additional product are sold per customer, given current penetration at 2.53 | N45: Card limit change | O45: =8736*70% -> 6115.2 | P45: 0.17 | Q45: =120*12 -> 1440 | R45: ='Extra Tables Parking lot'!F23 -> 0.16666667 | T45: ='Extra Tables Parking lot'!H23 -> 0.5 | U45: 0.35 | V45: Volumes in branch assumed for lack of accurate data from Seabank | W45: =O45/$O$55 -> 0.0075950593 | X45: =Q45/$Q$55 -> 0.017159199 | Y45: Assumption: integrated digital loan origination solution will help employee to service prospects more efficiently, and increase conversion.
N46: Credit card order request | Q46: ='Extra Tables Parking lot'!E24 -> 7000 | R46: ='Extra Tables Parking lot'!F24 -> 0.25 | T46: ='Extra Tables Parking lot'!H24 -> 0.5 | U46: 0.35 | V46: Data from seabank | W46: =O46/$O$55 -> 0 | X46: =Q46/$Q$55 -> 0.083412774
B47: Reduce Branch Visits | E47: Reduce Branch Visits | H47: FTE Hourly Rate $ | K47: Marketing Efficiency | N47: Deposit products enquiry | Q47: =150*12 -> 1800 | R47: ='Extra Tables Parking lot'!F25 -> 0.083333333 | S47: ='Extra Tables Parking lot'!G25 -> 0 | T47: ='Extra Tables Parking lot'!H25 -> 0 | U47: 0.35 | V47: Data from seabank | W47: =O47/$O$55 -> 0 | X47: =Q47/$Q$55 -> 0.021448999
B48: No of Visits/Calls/Tasks/Year | C48: =C42 -> 241471.25 | E48: No of Visits/Calls/Tasks/Year | F48: =F42 -> 103600 | G48: Assumption: ±1/3 loans was actually approved/disbursed; = branch walk-ins x3 of approved loans. | K48: Number of Marketing FTE | L48: 15 | M48: Assumption | N48: Bill payments | O48: =1248*(12/5) -> 2995.2 | P48: =10/60 -> 0.16666667 | Q48: =60*12 -> 720 | R48: ='Extra Tables Parking lot'!F26 -> 0.16666667 | S48: ='Extra Tables Parking lot'!G26 -> 0 | T48: ='Extra Tables Parking lot'!H26 -> 0 | U48: 0.1 | V48: Volumes in branch assumed for lack of accurate data from Seabank | W48: =O48/$O$55 -> 0.0037200291 | Y48: Assumption: ±1/3 loans was actually approved/disbursed; = branch walk-ins x3 of approved loans.
B49: Average Time Spent /Interaction (hours) | C49: =20/60 -> 0.33333333 | D49: Assuming 20 mins, 15 mins for account opening + time spent to consult & potential wait time | E49: Average Time Spent per Interaction (hours) | F49: =40/60 -> 0.66666667 | G49: Total average processing time per one personal loan disbursed. | H49: =F14 -> 8.0103948 | K49: Cost/FTE | L49: =I14/F16 -> 16020.79 | N49: International Transfers | O49: =462*(12/5) -> 1108.8 | P49: =30/60 -> 0.5 | Q49: =20*12 -> 240 | R49: ='Extra Tables Parking lot'!F27 -> 0.083333333 | T49: ='Extra Tables Parking lot'!H27 -> 0.25 | U49: 0.2 | V49: Volumes in branch assumed for lack of accurate data from Seabank | W49: =O49/$O$55 -> 0.0013771261 | X49: =Q49/$Q$55 -> 0.0028598665 | Y49: Total average processing time per one personal loan disbursed.
B50: Average FTE Costs per Hour (USD) | C50: =F14 -> 8.0103948 | D50: Calculated | E50: Average FTE Costs per Hour (USD) | F50: =F14 -> 8.0103948 | H50: Hour to Mins | I50: 60 | K50: Backbase Impact | L50: 0.35 | M50: Reduction in effort of manual campaign planning | N50: Customer Details Update / KYC details | O50: =86889*70% -> 60822.3 | P50: 0.17 | Q50: =140*12 -> 1680 | R50: ='Extra Tables Parking lot'!F28 -> 0.16666667 | S50: ='Extra Tables Parking lot'!G28 -> 0 | T50: ='Extra Tables Parking lot'!H28 -> 0 | U50: 0.35 | V50: Volumes in branch assumed for lack of accurate data from Seabank | W50: =O50/$O$55 -> 0.075541107 | X50: =Q50/$Q$55 -> 0.020019066
B51: Backbase Impact | C51: 0.3 | D51: 30% customers move to digital | E51: Backbase Impact | F51: 0.3 | G51: Assuming 30% move to digital | N51: Credit card info inquiry (& other CC servicing) | Q51: =1200*12 -> 14400 | R51: ='Extra Tables Parking lot'!F29 -> 0.16666667 | S51: ='Extra Tables Parking lot'!G29 -> 0 | T51: ='Extra Tables Parking lot'!H29 -> 0 | U51: 0.35 | V51: Data from seabank | W51: =O51/$O$55 -> 0 | X51: =Q51/$Q$55 -> 0.17159199 | Y51: Assuming 30% move to digital
...

Sheet Customer & Loan Acquisition - A
B2: Backbase VC-Business Case
B3: Customer and Loan Acquisition Analysis
C7: Required info
C8: Calculated Info
C9: Assumptions
B14: Customer Acquisition - Onboarding Value Drivers | C14: Total | D14: Impact | E14: Data Detail | H14: Total | I14: Year 1 | J14: Year 2 | K14: Year 3 | L14: Year 4 | M14: Year 5
B15: Sum of Customer Onboarding Value Drivers | C15: =sum(C16:C44) -> 24634790 | G15: Customer Onboarding (Cost Reduction + Revenue Improvement) | H15: =sUm(I15:M15) -> 1752132.6 | I15: =I19+I23 -> 29475.938 | J15: =J19+J23 -> 161712.99 | K15: =K19+K23 -> 327174.43 | L15: =L19+L23 -> 571638.87 | M15: =M19+M23 -> 662130.38
B16: Total Revenue Generation - Customer Acquisition | C16: =C23+C32 -> 1330563.3 | G16: Increase Revenue | H16: =sum(I16:M16) -> 714068.98 | I16: =I19 -> 14968.837 | J16: =J19 -> 34372.886 | K16: =K19 -> 124075.03 | L16: =L19 -> 249258.86 | M16: =M19 -> 291393.37
B17: Increase Customer Conversion in website | C17: =C23 -> 1186151.4 | D17: Revenue Generation and Cost Reduction | G17: Average Income per New Customer | H17: =AVERAGE(I17:M17) -> 21.9285 | I17: =$C$155/4 -> 9.9675 | J17: =$C$155/3 -> 13.29 | K17: =$C$155/2 -> 19.935 | L17: =$C$155/1.5 -> 26.58 | M17: =$C$155/1 -> 39.87
B18: Website Visits - Intention to Purchase Product | C18: ='Customer Phases - Inputs and As'!C36 -> 514447 | G18: New Customers Acquired | H18: =SUM(I18:M18) -> 26998.388 | I18: =($C$25+$C$34)*'Customer Phases - Inputs and As'!C21*'Customer Phases - Inputs and As'!C22 -> 1501.7645 | J18: =(($C$25+$C$34)/2*'Customer Phases - Inputs and As'!D21*'Customer Phases - Inputs and As'!D22)-I18 -> 2586.3721 | K18: =(($C$25+$C$34)/2*'Customer Phases - Inputs and As'!E21*'Customer Phases - Inputs and As'!E22*1.1)-J18 -> 6223.9794 | L18: =(($C$25+$C$34)/2*'Customer Phases - Inputs and As'!F21*'Customer Phases - Inputs and As'!F22*1.1)-K18 -> 9377.6848 | M18: =(($C$25+$C$34)/2*'Customer Phases - Inputs and As'!G21*'Customer Phases - Inputs and As'!G22)-L18 -> 7308.5871
B19: Current Customer Leakage (%) | C19: ='Customer Phases - Inputs and As'!C37 -> 0.7710668 | E19: Current absolute leakage rate due to non-activation & non-completion of application | G19: Income form New Customers Acquired | H19: =SUM(I19:M19) -> 714068.98 | I19: =I17*I18 -> 14968.837 | J19: =J17*J18 -> 34372.886 | K19: =K17*K18 -> 124075.03 | L19: =L17*L18 -> 249258.86 | M19: =M17*M18 -> 291393.37
B20: Average Income/Customer | C20: ='Customer Phases - Inputs and As'!C38 -> 39.87 | G20: Reduce Costs | H20: =sum(I20:M20) -> 1038063.6 | I20: =I23 -> 14507.1 | J20: =J23 -> 127340.1 | K20: =K23 -> 203099.4 | L20: =L23 -> 322380.01 | M20: =M23 -> 370737.01
B21: Baseline | C21: =C20*C18*C19 -> 15815353 | E21: Customers Leakage Value (visits x leakage x revenue/product) | G21: Number of Physical Interactions and Tasks | H21: =SUM(I21:M21) -> 3256182.5 | I21: =C37+C53+C61+C45 -> 482942.5 | J21: =I21*(1+'Customer Phases - Inputs and As'!D23) -> 555383.88 | K21: =J21*(1+'Customer Phases - Inputs and As'!E23) -> 638691.46 | L21: =K21*(1+'Customer Phases - Inputs and As'!F23) -> 734495.17 | M21: =L21*(1+'Customer Phases - Inputs and As'!G23) -> 844669.45
B22: Backbase Impact | C22: ='Customer Phases - Inputs and As'!C39 -> 0.075 | E22: Post implementation % customers can be converted from leaked out due to digital | G22: Number of Physical Interactions and Tasks Converted to Digital | H22: =SUM(I22:M22) -> 814045.61 | I22: =C43+C59+C67+C51 -> 120735.62 | J22: =I22*(1+'Customer Phases - Inputs and As'!D23) -> 138845.97 | K22: =J22*(1+'Customer Phases - Inputs and As'!E23) -> 159672.86 | L22: =K22*(1+'Customer Phases - Inputs and As'!F23) -> 183623.79 | M22: =L22*(1+'Customer Phases - Inputs and As'!G23) -> 211167.36
B23: Potential Annual benefits | C23: =C21*C22 -> 1186151.4 | E23: Net more income that can be generated due to higher digital conversions | G23: Cost Saved | H23: =SUM(I23:M23) -> 1038063.6 | I23: =C35*'Customer Phases - Inputs and As'!C21*'Customer Phases - Inputs and As'!C22 -> 14507.1 | J23: =C35*'Customer Phases - Inputs and As'!D21*'Customer Phases - Inputs and As'!D22+C35*('Customer Phases - Inputs and As'!D23) -> 127340.1 | K23: =C35*'Customer Phases - Inputs and As'!E21*'Customer Phases - Inputs and As'!E22+C35*'Customer Phases - Inputs and As'!E23 -> 203099.4 | L23: =C35*'Customer Phases - Inputs and As'!F21*'Customer Phases - Inputs and As'!F22+C35*'Customer Phases - Inputs and As'!F23 -> 322380.01 | M23: =L23*'Customer Phases - Inputs and As'!G21*'Customer Phases - Inputs and As'!G22+L23*'Customer Phases - Inputs and As'!G23 -> 370737.01
B24: Current Customer Leakage # | C24: =C18*C19 -> 396673 | E24: Total No of Customer who could have been converted | G24: USL Origination (Cost Reduction + Revenue Improvement) | H24: =sUm(I24:M24) -> 1351893.8 | I24: =I28+I32 -> 12783.367 | J24: =J28+J32 -> 112021.23 | K24: =K28+K32 -> 211735.33 | L24: =L28+L32 -> 392046.65 | M24: =M28+M32 -> 623307.26
B25: Net More Customers Acquired | C25: =C24*C22 -> 29750.475 | E25: No of customer who could be converted after applying Backbase impact | G25: Increase Revenue | H25: =sum(I25:M25) -> 639306.21 | I25: =I28 -> 2824.8443 | J25: =J28 -> 24607.533 | K25: =K28 -> 72316.015 | L25: =L28 -> 170746.15 | M25: =M28 -> 368811.67
B26: Increase Customer Conversion in Branch sales | C26: =C32 -> 144411.88 | D26: Revenue Generation | G26: Average Income per New Customer | H26: =SUM(I26:M26) -> 109.6425 | I26: =$C$74/4 -> 9.9675 | J26: =$C$74/3 -> 13.29 | K26: =$C$74/2 -> 19.935 | L26: =$C$74/1.5 -> 26.58 | M26: =$C$74/1 -> 39.87
B27: No of Visits/Year | C27: ='Customer Phases - Inputs and As'!C42 -> 241471.25 | E27: Customer visiting branch; | G27: New Loans Acquisitions | H27: =SUM(I27:M27) -> 21436.792 | I27: =(($C$79+$C$88)*'Customer Phases - Inputs and As'!C21*'Customer Phases - Inputs and As'!C22) -> 283.4055 | J27: =(($C$79+$C$88)*'Customer Phases - Inputs and As'!D21*'Customer Phases - Inputs and As'!D22)*(1+'Customer Phases - Inputs and As'!F76) -> 1851.5826 | K27: =(($C$79+$C$88)*'Customer Phases - Inputs and As'!E21*'Customer Phases - Inputs and As'!E22)*((1+'Customer Phases - Inputs and As'!F76)) -> 3627.5904 | L27: =(($C$79+$C$88)*'Customer Phases - Inputs and As'!F21*'Customer Phases - Inputs and As'!F22)*((1+'Customer Phases - Inputs and As'!F76)) -> 6423.858 | M27: =((L27*'Customer Phases - Inputs and As'!G21*'Customer Phases - Inputs and As'!G22)*((1+'Customer Phases - Inputs and As'!F76)^2)) -> 9250.3555
B28: Current Customer Leakage (%) | C28: ='Customer Phases - Inputs and As'!C43 -> 0.2 | E28: Current absolute leakage rate including activation leakage | G28: Income form New Loans Acquisitions | H28: =SUM(I28:M28) -> 639306.21 | I28: =I27*I26 -> 2824.8443 | J28: =J27*J26 -> 24607.533 | K28: =K27*K26 -> 72316.015 | L28: =L27*L26 -> 170746.15 | M28: =M27*M26 -> 368811.67
B29: Average Income/Customer | C29: ='Customer Phases - Inputs and As'!C44 -> 39.87 | G29: Reduce Costs | H29: =sum(I29:M29) -> 712587.63 | I29: =I32 -> 9958.5228 | J29: =J32 -> 87413.7 | K29: =K32 -> 139419.32 | L29: =L32 -> 221300.51 | M29: =M32 -> 254495.58
B30: Baseline | C30: =C29*C27*C28 -> 1925491.7 | E30: Customers Leakage Value | G30: Number of Physical Interactions and Tasks | H30: =SUM(I30:M30) -> 1047766 | I30: =C91+C99+C107+C115 -> 155400 | J30: =I30*(1+'Customer Phases - Inputs and As'!D23) -> 178710 | K30: =J30*(1+'Customer Phases - Inputs and As'!E23) -> 205516.5 | L30: =K30*(1+'Customer Phases - Inputs and As'!F23) -> 236343.98 | M30: =L30*(1+'Customer Phases - Inputs and As'!G23) -> 271795.57
B31: Backbase Impact | C31: ='Customer Phases - Inputs and As'!C45 -> 0.075 | E31: Assumption: Integrated digital onboarding solution will remove friction in the onboarding process across branch/digital channels | G31: Number of Physical Interactions and Tasks Converted to Digital | H31: =SUM(I31:M31) -> 279404.28 | I31: =C97+C105+C113+C121 -> 41440 | J31: =I31*(1+'Customer Phases - Inputs and As'!D23) -> 47656 | K31: =J31*(1+'Customer Phases - Inputs and As'!E23) -> 54804.4 | L31: =K31*(1+'Customer Phases - Inputs and As'!F23) -> 63025.06 | M31: =L31*(1+'Customer Phases - Inputs and As'!G23) -> 72478.819
B32: Potential Annual benefits | C32: =C30*C31 -> 144411.88 | E32: Net more income that can be generated due to higher conversions | G32: Cost Saved | H32: =SUM(I32:M32) -> 712587.63 | I32: =C89*'Customer Phases - Inputs and As'!C21*'Customer Phases - Inputs and As'!C22 -> 9958.5228 | J32: =$C$89*'Customer Phases - Inputs and As'!D21*'Customer Phases - Inputs and As'!D22+$C$89*'Customer Phases - Inputs and As'!D23 -> 87413.7 | K32: =C89*'Customer Phases - Inputs and As'!E21*'Customer Phases - Inputs and As'!E22+C89*'Customer Phases - Inputs and As'!E23 -> 139419.32 | L32: =C89*'Customer Phases - Inputs and As'!F21*'Customer Phases - Inputs and As'!F22+C89*'Customer Phases - Inputs and As'!F23 -> 221300.51 | M32: =L32*'Customer Phases - Inputs and As'!G21*'Customer Phases - Inputs and As'!G22+L32*'Customer Phases - Inputs and As'!G23 -> 254495.58
B33: Current Customer Leakage # | C33: =C27*C28 -> 48294.25 | E33: No of Customer who could have been converted | G33: CLO (Cost Reduction + Revenue Improvement) | H33: =sUm(I33:M33) -> 7952116.8 | I33: =(I37+I41)*0 -> 0 | J33: =J37+J41 -> 765378.88 | K33: =K37+K41 -> 1487416.4 | L33: =L37+L41 -> 2619573.4 | M33: =M37+M41 -> 3079748.2
B34: Net More Customers Acquired | C34: =C33*C31 -> 3622.0687 | E34: No of customer who could be converted after applying Backbase impact | G34: Increase Revenue | H34: =sum(I34:M34) -> 7695106.6 | I34: =I37*0 -> 0 | J34: =J37 -> 732155.77 | K34: =K37 -> 1434427.6 | L34: =L37 -> 2540132.3 | M34: =M37 -> 2988390.9
B35: Total Cost Benefit - Customer Acquisition | C35: =C42+C58+C66+C50 -> 322380.01 | G35: Average Income per Customer (Additional) | H35: =SUM(I35:M35) -> 106.32 | I35: =$C$128/4 -> 9.9675 | J35: =$C$128/4 -> 9.9675 | K35: =$C$128/2 -> 19.935 | L35: =$C$128/1.5 -> 26.58 | M35: =$C$128 -> 39.87
B36: Reduce Branch Visits | C36: =C42 -> 193428 | D36: Cost Reduction | G36: Reactivate Dorman Customers | H36: =SUM(I36:M36) -> 7829584.2 | I36: =(($C$131)*'Customer Phases - Inputs and As'!C21*'Customer Phases - Inputs and As'!C22) -> 134477.59 | J36: =(($C$131)*'Customer Phases - Inputs and As'!D21*'Customer Phases - Inputs and As'!D22)*((1+'Customer Phases - Inputs and As'!X76)) -> 732155.77 | K36: =(($C$131)*'Customer Phases - Inputs and As'!E21*'Customer Phases - Inputs and As'!E22)*((1+'Customer Phases - Inputs and As'!X76)^2) -> 1434427.6 | L36: =(($C$131)*'Customer Phases - Inputs and As'!F21*'Customer Phases - Inputs and As'!F22)*((1+'Customer Phases - Inputs and As'!X76)^3) -> 2540132.3 | M36: =(($C$131)*'Customer Phases - Inputs and As'!G21*'Customer Phases - Inputs and As'!G22)*((1+'Customer Phases - Inputs and As'!X76)^3) -> 2988390.9
B37: No of Visits/Calls/Tasks/Year | C37: ='Customer Phases - Inputs and As'!C48 -> 241471.25 | E37: Volume of physical interactions or back office tasks created | G37: Product cross sell and upsell | H37: =SUM(I37:M37) -> 7829584.2 | I37: =(($C$140)*'Customer Phases - Inputs and As'!C21*'Customer Phases - Inputs and As'!C22) -> 134477.59 | J37: =(($C$140)*'Customer Phases - Inputs and As'!D21*'Customer Phases - Inputs and As'!D22)*((1+'Customer Phases - Inputs and As'!X76)) -> 732155.77 | K37: =(($C$140)*'Customer Phases - Inputs and As'!E21*'Customer Phases - Inputs and As'!E22)*((1+'Customer Phases - Inputs and As'!X76)^2) -> 1434427.6 | L37: =(($C$140)*'Customer Phases - Inputs and As'!F21*'Customer Phases - Inputs and As'!F22)*((1+'Customer Phases - Inputs and As'!X76)^3) -> 2540132.3 | M37: =(($C$140)*'Customer Phases - Inputs and As'!G21*'Customer Phases - Inputs and As'!G22)*((1+'Customer Phases - Inputs and As'!X76)^3) -> 2988390.9
B38: Average Time Spent /Interaction (hours) | C38: ='Customer Phases - Inputs and As'!C49 -> 0.33333333 | E38: Time spent on 1 visit, call or task | G38: Reduce Costs | H38: =sum(I38:M38) -> 257010.21 | I38: =I41*0 -> 0 | J38: =J41 -> 33223.112 | K38: =K41 -> 52988.762 | L38: =L41 -> 79441.088 | M38: =M41 -> 91357.251
B39: Average FTE Costs/Hour (USD) | C39: ='Customer Phases - Inputs and As'!C50 -> 8.0103948 | E39: assumed employee cost per hour | G39: Improve marketing team's operational efficiency | H39: =SUM(I39:M39) -> 567095.92 | I39: =C144 -> 84109.145 | J39: =I39*(1+'Customer Phases - Inputs and As'!D23) -> 96725.517 | K39: =J39*(1+'Customer Phases - Inputs and As'!E23) -> 111234.34 | L39: =K39*(1+'Customer Phases - Inputs and As'!F23) -> 127919.5 | M39: =L39*(1+'Customer Phases - Inputs and As'!G23) -> 147107.42
B40: Baseline | C40: =C39*C38*C37 -> 644760.01 | E40: Total monetary value spent on interactions
B41: Backbase Impact | C41: ='Customer Phases - Inputs and As'!C51 -> 0.3 | E41: Post Implementation due to digital adoption traffic will move to digital channels | G41: Cost Saved | H41: =SUM(I41:M41) -> 260795.12 | I41: =C143*'Customer Phases - Inputs and As'!C21*'Customer Phases - Inputs and As'!C22 -> 3784.9115 | J41: =$C$143*'Customer Phases - Inputs and As'!D21*'Customer Phases - Inputs and As'!D22+$C$143*'Customer Phases - Inputs and As'!D23 -> 33223.112 | K41: =C143*'Customer Phases - Inputs and As'!E21*'Customer Phases - Inputs and As'!E22+C143*'Customer Phases - Inputs and As'!E23 -> 52988.762 | L41: =C143*'Customer Phases - Inputs and As'!F21*'Customer Phases - Inputs and As'!F22+K41*'Customer Phases - Inputs and As'!F23 -> 79441.088 | M41: =L41*'Customer Phases - Inputs and As'!G21*'Customer Phases - Inputs and As'!G22+L41*'Customer Phases - Inputs and As'!G23 -> 91357.251
B42: Potential Annual benefits | C42: =C40*C41 -> 193428 | E42: Net costs that can be saved | G42: Customer Loyalty and Retention | H42: =sUm(I42:M42) -> 6375921.5 | I42: =I43+I44 -> 109418.84 | J42: =J43+J44 -> 596367.66 | K42: =K43+K44 -> 1168393.8 | L42: =L43+L44 -> 2069030.7 | M42: =M43+M44 -> 2432710.5
B43: Net Decrease in Traffic/Year | C43: =C41*C37 -> 72441.375 | E43: No of interactions moved to digital | G43: Improve Customer Churn | H43: =SUM(I43:M43) -> 74061.073 | I43: =($C$152)*'Customer Phases - Inputs and As'!C27*'Customer Phases - Inputs and As'!C28 -> 1180.7788 | J43: =($C$152)*'Customer Phases - Inputs and As'!D27*'Customer Phases - Inputs and As'!D28*(1+'Customer Phases - Inputs and As'!C29) -> 7071.5533 | K43: =($C$152)*'Customer Phases - Inputs and As'!E27*'Customer Phases - Inputs and As'!E28*(1+'Customer Phases - Inputs and As'!C29) -> 13854.472 | L43: =($C$152)*'Customer Phases - Inputs and As'!F28*(1+'Customer Phases - Inputs and As'!C29) -> 24533.96 | M43: =($C$152/1)*'Customer Phases - Inputs and As'!E29*(1+'Customer Phases - Inputs and As'!C29)+L43 -> 27420.309
B44: Reduce Back Office Tasks | C44: =C50 -> 0 | D44: Cost Reduction | G44: Increase Product Penetration | H44: =SUM(I44:M44) -> 6301860.4 | I44: =$C$159*'Customer Phases - Inputs and As'!J27*'Customer Phases - Inputs and As'!J28 -> 108238.06 | J44: =$C$159*'Customer Phases - Inputs and As'!K28*'Customer Phases - Inputs and As'!K27 -> 589296.11 | K44: =$C$159*'Customer Phases - Inputs and As'!L28*'Customer Phases - Inputs and As'!L27 -> 1154539.3 | L44: =$C$159*'Customer Phases - Inputs and As'!M28*'Customer Phases - Inputs and As'!M27 -> 2044496.7 | M44: =$C$159*'Customer Phases - Inputs and As'!N28*'Customer Phases - Inputs and As'!N27 -> 2405290.2
B45: No of Visits/Calls/Tasks/Year | C45: ='Customer Phases - Inputs and As'!C66 -> 0 | E45: Volume of physical interactions or back office tasks created | G45: Customer Servicing | H45: =sUm(I45:M45) -> 842505.67 | I45: =I46+I47 -> 12854.408 | J45: =J46+J47 -> 69537.207 | K45: =K46+K47 -> 137113.69 | L45: =L46+L47 -> 242795.54 | M45: =M46+M47 -> 380204.83
B46: Average Time Spent /Interaction (hour) | C46: ='Customer Phases - Inputs and As'!C67 -> 0 | E46: Time spent on 1 visit, call or task | G46: Cost Avoidance | H46: =SUM(I46:M46) -> 842505.67 | I46: ='Servicing - Analysis'!C92 -> 12854.408 | J46: ='Servicing - Analysis'!D92 -> 69537.207 | K46: ='Servicing - Analysis'!F92 -> 137113.69 | L46: ='Servicing - Analysis'!G92 -> 242795.54 | M46: ='Servicing - Analysis'!H92 -> 380204.83
B47: Average FTE Costs/Hour (USD) | C47: ='Customer Phases - Inputs and As'!C68 -> 8.0103948 | E47: Based on average monthly salary
B48: Baseline | C48: =C47*C46*C45 -> 0 | E48: Total monetary value spent on interactions
...

Sheet Servicing - Analysis
B2: Backbase VC-Business Case
B3: Servicing Analysis
C7: Required info
C8: Calculated Info
C9: Assumptions
B14: Servicing Journey Names | C14: Yearly Volume | D14: Time Spent/Visit (HR) | F14: Baseline (Annual Cost) | G14: Backbase Impact | H14: After Impact
B15: Total | C15: =sum(C17:C33,C35:C51,C53:C69) -> 877075 | F15: =F16+F34+F52 -> 1259014.1 | H15: =H16+H34+H52 -> 331529.51
B16: Branch | C16: =sum(C17:C33) -> 805155 | F16: =sum(F17:F33) -> 1173463 | H16: =sum(H17:H33) -> 301802.93
B17: Accounts & Balance | C17: ='Customer Phases - Inputs and As'!O37 -> 105168.7 | D17: ='Customer Phases - Inputs and As'!P37 -> 0.08 | F17: =C17*D17*'Customer Phases - Inputs and As'!$H$49 -> 67395.425 | G17: ='Customer Phases - Inputs and As'!U37 -> 0.35 | H17: =F17*G17 -> 23588.399
B18: Account Statement | C18: ='Customer Phases - Inputs and As'!O38 -> 75120.5 | D18: ='Customer Phases - Inputs and As'!P38 -> 0.17 | F18: =C18*D18*'Customer Phases - Inputs and As'!$H$49 -> 102296.63 | G18: ='Customer Phases - Inputs and As'!U38 -> 0.4 | H18: =F18*G18 -> 40918.651
B19: Transaction Dispute | C19: ='Customer Phases - Inputs and As'!O39 -> 53787.3 | D19: ='Customer Phases - Inputs and As'!P39 -> 0.33 | F19: =C19*D19*'Customer Phases - Inputs and As'!$H$49 -> 142182.98 | G19: ='Customer Phases - Inputs and As'!U39 -> 0.4 | H19: =F19*G19 -> 56873.191
B20: Internal Transfers | C20: ='Customer Phases - Inputs and As'!O40 -> 356767.2 | D20: ='Customer Phases - Inputs and As'!P40 -> 0.16666667 | F20: =C20*D20*'Customer Phases - Inputs and As'!$H$49 -> 476307.69 | G20: ='Customer Phases - Inputs and As'!U40 -> 0.1 | H20: =F20*G20 -> 47630.769
B21: Inter Bank Transfers | C21: ='Customer Phases - Inputs and As'!O41 | D21: ='Customer Phases - Inputs and As'!P41 | F21: =C21*D21*'Customer Phases - Inputs and As'!$H$49 -> 0 | G21: ='Customer Phases - Inputs and As'!U41 -> 0.1 | H21: =F21*G21 -> 0
B22: Debit Card Ordering | C22: ='Customer Phases - Inputs and As'!O42 -> 7588.8 | D22: ='Customer Phases - Inputs and As'!P42 -> 0.25 | F22: =C22*D22*'Customer Phases - Inputs and As'!$H$49 -> 15197.321 | G22: ='Customer Phases - Inputs and As'!U42 -> 0.35 | H22: =F22*G22 -> 5319.0624
B23: Card block | C23: ='Customer Phases - Inputs and As'!O43 -> 1146.6 | D23: ='Customer Phases - Inputs and As'!P43 -> 0.17 | F23: =C23*D23*'Customer Phases - Inputs and As'!$H$49 -> 1561.4022 | G23: ='Customer Phases - Inputs and As'!U43 -> 0.2 | H23: =F23*G23 -> 312.28043
B24: Cards PIN reset | C24: ='Customer Phases - Inputs and As'!O44 -> 764.4 | D24: ='Customer Phases - Inputs and As'!P44 -> 0.17 | F24: =C24*D24*'Customer Phases - Inputs and As'!$H$49 -> 1040.9348 | G24: ='Customer Phases - Inputs and As'!U44 -> 0.2 | H24: =F24*G24 -> 208.18696
B25: Card limit change | C25: ='Customer Phases - Inputs and As'!O45 -> 6115.2 | D25: ='Customer Phases - Inputs and As'!P45 -> 0.17 | F25: =C25*D25*'Customer Phases - Inputs and As'!$H$49 -> 8327.4783 | G25: ='Customer Phases - Inputs and As'!U45 -> 0.35 | H25: =F25*G25 -> 2914.6174
B26: Credit card order request | C26: ='Customer Phases - Inputs and As'!O46 | D26: ='Customer Phases - Inputs and As'!P46 | F26: =C26*D26*'Customer Phases - Inputs and As'!$H$49 -> 0 | G26: ='Customer Phases - Inputs and As'!U46 -> 0.35 | H26: =F26*G26 -> 0
B27: Deposit products enquiry | C27: ='Customer Phases - Inputs and As'!O47 | D27: ='Customer Phases - Inputs and As'!P47 | F27: =C27*D27*'Customer Phases - Inputs and As'!$H$49 -> 0 | G27: ='Customer Phases - Inputs and As'!U47 -> 0.35 | H27: =F27*G27 -> 0
B28: Bill payments | C28: ='Customer Phases - Inputs and As'!O48 -> 2995.2 | D28: ='Customer Phases - Inputs and As'!P48 -> 0.16666667 | F28: =C28*D28*'Customer Phases - Inputs and As'!$H$49 -> 3998.7891 | G28: ='Customer Phases - Inputs and As'!U48 -> 0.1 | H28: =F28*G28 -> 399.87891
... B32: Loan Servicing | C32: ='Customer Phases - Inputs and As'!O52 -> 133770 | D32: ='Customer Phases - Inputs and As'!P52 -> 0.25 | F32: =C32*D32*'Customer Phases - Inputs and As'!$H$49 -> 267887.63 | G32: ='Customer Phases - Inputs and As'!U52 -> 0.35 | H32: =F32*G32 -> 93760.67
C33: ='Customer Phases - Inputs and As'!O53 | D33: ='Customer Phases - Inputs and As'!P53 | F33: =C33*D33*'Customer Phases - Inputs and As'!$H$49 -> 0 | G33: ='Customer Phases - Inputs and As'!U53 | H33: =F33*G33 -> 0
B34: Call Center | C34: =sum(C35:C51) -> 71920 | F34: =sum(F35:F51) -> 85551.016 | H34: =sum(H35:H51) -> 29726.575
B35: Accounts & Balance | C35: ='Customer Phases - Inputs and As'!Q37 -> 18720 | D35: ='Customer Phases - Inputs and As'!R37 -> 0.083333333 | F35: =C35*D35*'Customer Phases - Inputs and As'!$H$49 -> 12496.216 | G35: ='Customer Phases - Inputs and As'!U37 -> 0.35 | H35: =F35*G35 -> 4373.6756
B36: Account Statement | C36: ='Customer Phases - Inputs and As'!Q38 | D36: ='Customer Phases - Inputs and As'!R38 -> 0.16666667 | F36: =C36*D36*'Customer Phases - Inputs and As'!$H$49 -> 0 | G36: ='Customer Phases - Inputs and As'!U38 -> 0.4 | H36: =F36*G36 -> 0
B37: Transaction Dispute | C37: ='Customer Phases - Inputs and As'!Q39 -> 4800 | D37: ='Customer Phases - Inputs and As'!R39 -> 0.25 | F37: =C37*D37*'Customer Phases - Inputs and As'!$H$49 -> 9612.4738 | G37: ='Customer Phases - Inputs and As'!U39 -> 0.4 | H37: =F37*G37 -> 3844.9895
B38: Internal Transfers | C38: 0 | D38: ='Customer Phases - Inputs and As'!R40 -> 0.083333333 | F38: =C38*D38*'Customer Phases - Inputs and As'!$H$49 -> 0 | G38: ='Customer Phases - Inputs and As'!U40 -> 0.1 | H38: =F38*G38 -> 0
B39: Inter Bank Transfers | C39: ='Customer Phases - Inputs and As'!Q41 -> 0 | D39: ='Customer Phases - Inputs and As'!R41 -> 0.16666667 | F39: =C39*D39*'Customer Phases - Inputs and As'!$H$49 -> 0 | G39: ='Customer Phases - Inputs and As'!U41 -> 0.1 | H39: =F39*G39 -> 0
B40: Debit Card Ordering | C40: ='Customer Phases - Inputs and As'!Q42 -> 1080 | D40: ='Customer Phases - Inputs and As'!R42 -> 0.16666667 | F40: =C40*D40*'Customer Phases - Inputs and As'!$H$49 -> 1441.8711 | G40: ='Customer Phases - Inputs and As'!U42 -> 0.35 | H40: =F40*G40 -> 504.65487
B41: Card block | C41: ='Customer Phases - Inputs and As'!Q43 -> 5280 | D41: ='Customer Phases - Inputs and As'!R43 -> 0.083333333 | F41: =C41*D41*'Customer Phases - Inputs and As'!$H$49 -> 3524.5737 | G41: ='Customer Phases - Inputs and As'!U43 -> 0.2 | H41: =F41*G41 -> 704.91474
B42: Cards PIN reset | C42: ='Customer Phases - Inputs and As'!Q44 -> 1440 | D42: ='Customer Phases - Inputs and As'!R44 -> 0.083333333 | F42: =C42*D42*'Customer Phases - Inputs and As'!$H$49 -> 961.24738 | G42: ='Customer Phases - Inputs and As'!U44 -> 0.2 | H42: =F42*G42 -> 192.24948
B43: Card limit change | C43: ='Customer Phases - Inputs and As'!Q45 -> 1440 | D43: ='Customer Phases - Inputs and As'!R45 -> 0.16666667 | F43: =C43*D43*'Customer Phases - Inputs and As'!$H$49 -> 1922.4948 | G43: ='Customer Phases - Inputs and As'!U45 -> 0.35 | H43: =F43*G43 -> 672.87316
B44: Credit card order request | C44: ='Customer Phases - Inputs and As'!Q46 -> 7000 | D44: ='Customer Phases - Inputs and As'!R46 -> 0.25 | F44: =C44*D44*'Customer Phases - Inputs and As'!$H$49 -> 14018.191 | G44: ='Customer Phases - Inputs and As'!U46 -> 0.35 | H44: =F44*G44 -> 4906.3668
B45: Deposit products enquiry | C45: ='Customer Phases - Inputs and As'!Q47 -> 1800 | D45: ='Customer Phases - Inputs and As'!R47 -> 0.083333333 | F45: =C45*D45*'Customer Phases - Inputs and As'!$H$49 -> 1201.5592 | G45: ='Customer Phases - Inputs and As'!U47 -> 0.35 | H45: =F45*G45 -> 420.54573
B46: Bill payments | C46: 0 | D46: ='Customer Phases - Inputs and As'!R48 -> 0.16666667 | F46: =C46*D46*'Customer Phases - Inputs and As'!$H$49 -> 0 | G46: ='Customer Phases - Inputs and As'!U48 -> 0.1 | H46: =F46*G46 -> 0
B47: International Transfers | C47: ='Customer Phases - Inputs and As'!Q49 -> 240 | D47: ='Customer Phases - Inputs and As'!R49 -> 0.083333333 | F47: =C47*D47*'Customer Phases - Inputs and As'!$H$49 -> 160.2079 | G47: ='Customer Phases - Inputs and As'!U49 -> 0.2 | H47: =F47*G47 -> 32.041579
B48: Customer Details Update / KYC details | C48: ='Customer Phases - Inputs and As'!Q50 -> 1680 | D48: ='Customer Phases - Inputs and As'!R50 -> 0.16666667 | F48: =C48*D48*'Customer Phases - Inputs and As'!$H$49 -> 2242.9105 | G48: ='Customer Phases - Inputs and As'!U50 -> 0.35 | H48: =F48*G48 -> 785.01869
B49: Credit card info inquiry (& other CC servicing) | C49: ='Customer Phases - Inputs and As'!Q51 -> 14400 | D49: ='Customer Phases - Inputs and As'!R51 -> 0.16666667 | F49: =C49*D49*'Customer Phases - Inputs and As'!$H$49 -> 19224.948 | G49: ='Customer Phases - Inputs and As'!U51 -> 0.35 | H49: =F49*G49 -> 6728.7316
B50: Loan Servicing | C50: ='Customer Phases - Inputs and As'!Q52 -> 14040 | D50: ='Customer Phases - Inputs and As'!R52 -> 0.16666667 | F50: =C50*D50*'Customer Phases - Inputs and As'!$H$49 -> 18744.324 | G50: ='Customer Phases - Inputs and As'!U52 -> 0.35 | H50: =F50*G50 -> 6560.5133
C51: ='Customer Phases - Inputs and As'!Q53 | D51: ='Customer Phases - Inputs and As'!R53 | F51: =C51*D51*'Customer Phases - Inputs and As'!$H$49 -> 0 | G51: ='Customer Phases - Inputs and As'!U53 | H51: =F51*G51 -> 0
...

Sheet Extra Tables  Parking lot
C1: Net Income per Product | F1: Upsell Income per Product | I1: total digitally inactive customers | J1: ='Customer Phases - Inputs and As'!I13-750000 -> -749997.47
C2: Retail | D2: SME* | F2: Retail | G2: SME | I2: - 24/7 interbank transfer: | J2: 55932945
B3: Deposit Products | C3: ='Customer Phases - Inputs and As'!$C$38 -> 39.87 | D3: ='Customer Phases - Inputs and As'!$F$38 -> 39.87 | E3: Income /Customer* | I3: - Regular interbank transfer: | J3: 2869952 | L3: Legend
B4: Lending Products | E4: Upsell Income /Customer* | I4: - Internal transfer: | J4: 10645277 | L4: Assumed figure / extrapolated
C5: Average Income Per Product | F5: Average Income Per Segment | J5: 69448174 | L5: Data from HPB
I6: - Billing: | J6: 3897914
I7: - QR payment: | J7: 713022
I8: - Topup: | J8: 2780212
J9: 7391148
B10: ORIGINAL SERVICING CALCULATION - Retail + SME | I10: total CCs | J10: 273000 | L10: CC orders per month | M10: =50000/6 -> 8333.3333
C11: Servicing Journey Names: Retail and SME
C13: Branch | E13: Call Center | G13: Back-Office | I13: Impact | K13: Digital
B14: Service | C14: Volume | D14: Time Spent in HR | E14: Volume | F14: Time Spent in HR | G14: Volume | H14: Time Spent in HR | I14: Backbase Impact | J14: Notes | K14: Volume | L14: Time Spent in HR
B15: Accounts & Balance | C15: =J1*0.07 -> -52499.823 | D15: 0.083333333 | E15: =J1*0.09 -> -67499.772 | F15: 0.083333333 | G15: 0 | H15: 0 | I15: 0.35
B16: Account Statement | C16: =J1*0.05 -> -37499.874 | D16: 0.16666667 | E16: =C16/4 -> -9374.9684 | F16: 0.16666667 | I16: 0.45 | J16: back-office not involved
B17: Transaction Dispute | C17: =(J5+J9)*0.001 -> 76839.322 | D17: 0.33333333 | E17: =C17*2 -> 153678.64 | F17: 0.25 | G17: =(C17+E17)/2.5 -> 92207.186 | H17: 0.75 | I17: 0.45 | J17: Assumed as 1.7% of total service requests (HBR article on disputes), every dispute creates back-office task
B18: Internal Transfers | C18: =K18*0.2 -> 2129055.4 | D18: 0.16666667 | E18: - | F18: 0.083333333 | G18: 0 | H18: 0 | I18: 0.1 | J18: assuming 80% digital transfers; | K18: =J4 -> 10645277
B19: Inter Bank Transfers | C19: =K19*0.2 -> 11760579 | D19: 0.16666667 | E19: 0 | F19: 0.16666667 | G19: 0 | H19: 0.083333333 | I19: 0.1 | K19: =J3+J2 -> 58802897
B20: Debit Card Ordering | C20: ='Customer Phases - Inputs and As'!C73*0.1 -> 60937.7 | D20: =20/60 -> 0.33333333 | E20: =C20*0.13 -> 7921.901 | F20: =10/60 -> 0.16666667 | G20: =C20 -> 60937.7 | H20: 0.5 | I20: 0.5 | J20: using benchmarks - assuming 10% of all NTBs request for debit card
B21: Card block | C21: =J10*0.006 -> 1638 | D21: 0.16666667 | E21: =J10*0.01 -> 2730 | F21: 0.083333333 | G21: 0 | H21: 0 | I21: 0.2 | J21: back-office not involved
B22: Cards PIN reset | C22: =J10*0.004 -> 1092 | D22: 0.16666667 | E22: =J10*0.005 -> 1365 | F22: 0.083333333 | G22: 0 | H22: 0 | I22: 0.2 | J22: back-office not involved
B23: Card limit change | C23: =J10*0.032 -> 8736 | D23: 0.16666667 | E23: =J10*0.02 -> 5460 | F23: =10/60 -> 0.16666667 | G23: =C23+E23 -> 14196 | H23: =30/60 -> 0.5 | I23: 0.35 | J23: back-office in review & appraisal
B24: Credit card order request | C24: =(M10*0.7*12) -> 70000 | D24: =20/60 -> 0.33333333 | E24: =C24*0.1 -> 7000 | F24: =15/60 -> 0.25 | G24: =M10*12 -> 100000 | H24: 0.5 | I24: 0.35 | J24: back-office involved in review appraisal, card ordering/mailing
B25: Deposit products enquiry | C25: =J1*0.05 -> -37499.874 | D25: 0.083333333 | E25: =C25*2 -> -74999.747 | F25: 0.083333333 | G25: 0 | H25: 0 | I25: 0.4 | J25: Assumption: x2 product information inquiries in CC vs branch
B26: Bill payments | C26: =K26*0.012 -> 46774.968 | D26: 0.16666667 | E26: - | F26: 0.16666667 | G26: 0 | H26: 0 | I26: 0.1 | K26: =J6 -> 3897914
B27: International Transfers | C27: 200 | D27: =15/60 -> 0.25 | E27: 160 | F27: 0.083333333 | G27: 300 | H27: 0.25 | I27: 0.2
B28: Customer Details Update / KYC details | C28: ='Customer Phases - Inputs and As'!I13*0.03 -> 0.0759 | D28: =10/60 -> 0.16666667 | E28: =C28*0.02 -> 0.001518 | F28: =10/60 -> 0.16666667 | G28: 0 | H28: 0 | I28: 0.35
B29: Credit card info inquiry (& other CC servicing) | C29: =J10*0.07 -> 19110 | D29: =10/60 -> 0.16666667 | E29: =J10*0.1 -> 27300 | F29: =10/60 -> 0.16666667 | G29: 0 | H29: 0 | I29: 0.4 | J29: Assumption: x2 product information inquiries in branch vs CC
B30: Loan Servicing | C30: =J10*0.7 -> 191100 | D30: =15/60 -> 0.25 | E30: =J10*0.3 -> 81900 | F30: =10/60 -> 0.16666667 | G30: =(E30+C30)/10 -> 27300 | H30: 0.25 | I30: 0.5 | J30: Assuming 10% of servicing requests require BO involvement (ex: request to change schedule)
B33: Total interactions | C33: =SUM(C12:C31) -> 14238563 | E33: 280000 | G33: =SUM(G12:G31) -> 294940.89
C41: 215752500000
D42: =215/16840 -> 0.012767221
D43: =215/6900 -> 0.03115942
C50: Year 1 | D50: Year 2 | E50: Year 3 | F50: Year 4 | G50: Year 5 | H50: Total
C51: Revenue Growth
B52: New Customer Onboarding | C52: ='Customer & Loan Acquisition - A'!I$19 -> 14968.837 | D52: ='Customer & Loan Acquisition - A'!J$19 -> 34372.886 | E52: ='Customer & Loan Acquisition - A'!K$19 -> 124075.03 | F52: ='Customer & Loan Acquisition - A'!L$19 -> 249258.86 | G52: ='Customer & Loan Acquisition - A'!M$19 -> 291393.37 | H52: =SUM(C52:G52) -> 714068.98
B53: Lending Origination (USL) | C53: ='Customer & Loan Acquisition - A'!I$28 -> 2824.8443 | D53: ='Customer & Loan Acquisition - A'!J$28 -> 24607.533 | E53: ='Customer & Loan Acquisition - A'!K$28 -> 72316.015 | F53: ='Customer & Loan Acquisition - A'!L$28 -> 170746.15 | G53: ='Customer & Loan Acquisition - A'!M$28 -> 368811.67 | H53: =SUM(C53:G53) -> 639306.21
B54: CC Origination | C54: ='Customer & Loan Acquisition - A'!I37 -> 134477.59 | D54: ='Customer & Loan Acquisition - A'!J37 -> 732155.77 | E54: ='Customer & Loan Acquisition - A'!K37 -> 1434427.6 | F54: ='Customer & Loan Acquisition - A'!L37 -> 2540132.3 | G54: ='Customer & Loan Acquisition - A'!M37 -> 2988390.9 | H54: =SUM(C54:G54) -> 7829584.2
B55: Customer Retention | C55: ='Customer & Loan Acquisition - A'!I$43 -> 1180.7788 | D55: ='Customer & Loan Acquisition - A'!J$43 -> 7071.5533 | E55: ='Customer & Loan Acquisition - A'!K$43 -> 13854.472 | F55: ='Customer & Loan Acquisition - A'!L$43 -> 24533.96 | G55: ='Customer & Loan Acquisition - A'!M$43 -> 27420.309 | H55: =SUM(C55:G55) -> 74061.073
B56: Product Upsell | C56: ='Customer & Loan Acquisition - A'!I$44 -> 108238.06 | D56: ='Customer & Loan Acquisition - A'!J$44 -> 589296.11 | E56: ='Customer & Loan Acquisition - A'!K$44 -> 1154539.3 | F56: ='Customer & Loan Acquisition - A'!L$44 -> 2044496.7 | G56: ='Customer & Loan Acquisition - A'!M$44 -> 2405290.2 | H56: =SUM(C56:G56) -> 6301860.4
...

Sheet IT Cost Savings - Inputs and An
B2: Backbase VC-Business Case
B3: IT Cost Saving Analysis
C7: Required info
C8: Calculated Info
C9: Assumptions
C14: System Name | D14: Total | E14: 1 | F14: 2 | G14: 3 | H14: 4 | I14: 5 | J14: 6 | K14: 7 | L14: 8 | M14: 9 | N14: 10 | O14: 11 | P14: 12 | Q14: 13 | R14: 14 | S14: 15
C15: Customer licenses Costs | D15: =sum(E15:S15) -> 7000000 | E15: 1000000 | F15: 1500000 | G15: 1500000 | H15: 1500000 | I15: 1500000
C16: Implementation costs | D16: =sum(E16:S16) -> 4000000 | E16: 2000000 | F16: 500000 | G16: 500000 | H16: 500000 | I16: 500000
C21: Year | E21: Year 1 | F21: Year 2 | G21: Year 3 | H21: Year 4 | I21: Year 5
C22: Total Costs Saved (BB Effectiveness Applied) | D22: =SUM(E22:I22) -> 41800000 | E22: =sum(E23:E24)*('Customer Phases - Inputs and As'!C21) -> 3300000 | F22: =sum(F23:F24)*('Customer Phases - Inputs and As'!D21) -> 7700000 | G22: =sum(G23:G24)*('Customer Phases - Inputs and As'!E21) -> 8800000 | H22: =sum(H23:H24)*('Customer Phases - Inputs and As'!F21) -> 11000000 | I22: =sum(I23:I24)*('Customer Phases - Inputs and As'!G21) -> 11000000
C23: Customer licenses | D23: =sum(E23:I23) -> 35000000 | E23: =D15 -> 7000000 | F23: =E23 -> 7000000 | G23: =F23 -> 7000000 | H23: =G23 -> 7000000 | I23: =H23 -> 7000000
C24: Implementation costs | D24: =sum(E24:I24) -> 20000000 | E24: =D16 -> 4000000 | F24: =E24 -> 4000000 | G24: =F24 -> 4000000 | H24: =G24 -> 4000000 | I24: =H24 -> 4000000

Sheet Cashflows - Analysis
B2: Backbase VC-Business Case
B3: Cashflows
C7: Required info
C8: Calculated Info
C9: Assumptions
C13: Year 1 | D13: Year 2 | E13: Year 3 | F13: Year 4 | G13: Year 5 | H13: Total | J13: Discount Rate | M13: NPV | N13: {=NPV(J14,C30:G30)} -> 4054730.8
B14: Total Yearly Cash Inflow | C14: =C20+C15 -> 164532.55 | D14: =D20+D15 -> 1705018 | E14: =E20+E15 -> 3331833.6 | F14: =F20+F15 -> 5895085.1 | G14: =G20+G15 -> 7178101.2 | H14: =sum(C14:G14) -> 18274570 | J14: 0.1 | M14: ROI | N14: =H14+H25 -> 29274570 | O14: =(H14+H25)/H25 -> 2.6613246
B15: Revenue Generation | C15: =sum(C16:C19) -> 127212.52 | D15: =sum(D16:D19) -> 1387503.9 | E15: =sum(E16:E19) -> 2799212.5 | F15: =sum(F16:F19) -> 5029167.9 | G15: =sum(G16:G19) -> 6081306.5 | H15: =sum(C15:G15) -> 15424403 | J15: =H15/5 -> 3084880.7
B16: Customer Onboarding Revenue Generation | C16: ='Customer & Loan Acquisition - A'!I16 -> 14968.837 | D16: ='Customer & Loan Acquisition - A'!J16 -> 34372.886 | E16: ='Customer & Loan Acquisition - A'!K16 -> 124075.03 | F16: ='Customer & Loan Acquisition - A'!L16 -> 249258.86 | G16: ='Customer & Loan Acquisition - A'!M16 -> 291393.37 | H16: =sum(C16:G16) -> 714068.98 | J16: =H16/5 -> 142813.8
B17: Loan Origination Revenue Generation | C17: ='Customer & Loan Acquisition - A'!I25 -> 2824.8443 | D17: ='Customer & Loan Acquisition - A'!J25 -> 24607.533 | E17: ='Customer & Loan Acquisition - A'!K25 -> 72316.015 | F17: ='Customer & Loan Acquisition - A'!L25 -> 170746.15 | G17: ='Customer & Loan Acquisition - A'!M25 -> 368811.67 | H17: =sum(C17:G17) -> 639306.21 | J17: =H17/5 -> 127861.24
B18: CLO Revenue Generation | C18: ='Customer & Loan Acquisition - A'!I34 -> 0 | D18: ='Customer & Loan Acquisition - A'!J34 -> 732155.77 | E18: ='Customer & Loan Acquisition - A'!K34 -> 1434427.6 | F18: ='Customer & Loan Acquisition - A'!L34 -> 2540132.3 | G18: ='Customer & Loan Acquisition - A'!M34 -> 2988390.9 | H18: =sum(C18:G18) -> 7695106.6 | J18: =H18/5 -> 1539021.3
B19: Customer Loyalty and Retention | C19: ='Customer & Loan Acquisition - A'!I42 -> 109418.84 | D19: ='Customer & Loan Acquisition - A'!J42 -> 596367.66 | E19: ='Customer & Loan Acquisition - A'!K42 -> 1168393.8 | F19: ='Customer & Loan Acquisition - A'!L42 -> 2069030.7 | G19: ='Customer & Loan Acquisition - A'!M42 -> 2432710.5 | H19: =sum(C19:G19) -> 6375921.5 | J19: =H19/5 -> 1275184.3
B20: Cost Reduction | C20: =SUM(C21:C24) -> 37320.031 | D20: =SUM(D21:D24) -> 317514.12 | E20: =SUM(E21:E24) -> 532621.17 | F20: =SUM(F21:F24) -> 865917.15 | G20: =SUM(G21:G24) -> 1096794.7 | H20: =SUM(C20:G20) -> 2850167.1 | J20: =H20/5 -> 570033.43 | M20: Payback Period | N20: =if(C32>0,1+-C30/C30,if(D32>0,1+-C30/D30,if(E32>0,1+-C30/E30,if(F32>0,1+-C30/F30,if(G32>0,1+-C30/G30))))) -> 1.7279603
B21: Customer Onboarding Cost Reduction | C21: ='Customer & Loan Acquisition - A'!I20 -> 14507.1 | D21: ='Customer & Loan Acquisition - A'!J20 -> 127340.1 | E21: ='Customer & Loan Acquisition - A'!K20 -> 203099.4 | F21: ='Customer & Loan Acquisition - A'!L20 -> 322380.01 | G21: ='Customer & Loan Acquisition - A'!M20 -> 370737.01 | H21: =sum(C21:G21) -> 1038063.6 | J21: =H21/5 -> 207612.72 | M21: IRR | N21: =IRR(C30:G30) -> 0.45666217
B22: Loan Origination Cost Reduction | C22: ='Customer & Loan Acquisition - A'!I29 -> 9958.5228 | D22: ='Customer & Loan Acquisition - A'!J29 -> 87413.7 | E22: ='Customer & Loan Acquisition - A'!K29 -> 139419.32 | F22: ='Customer & Loan Acquisition - A'!L29 -> 221300.51 | G22: ='Customer & Loan Acquisition - A'!M29 -> 254495.58 | H22: =sum(C22:G22) -> 712587.63 | J22: =H22/5 -> 142517.53
B23: CLO Cost Reduction | C23: ='Customer & Loan Acquisition - A'!I38 -> 0 | D23: ='Customer & Loan Acquisition - A'!J38 -> 33223.112 | E23: ='Customer & Loan Acquisition - A'!K38 -> 52988.762 | F23: ='Customer & Loan Acquisition - A'!L38 -> 79441.088 | G23: ='Customer & Loan Acquisition - A'!M38 -> 91357.251 | H23: =sum(C23:G23) -> 257010.21 | J23: =H23/5 -> 51402.043
B24: Customer Servicing | C24: ='Customer & Loan Acquisition - A'!I46 -> 12854.408 | D24: ='Customer & Loan Acquisition - A'!J46 -> 69537.207 | E24: ='Customer & Loan Acquisition - A'!K46 -> 137113.69 | F24: ='Customer & Loan Acquisition - A'!L46 -> 242795.54 | G24: ='Customer & Loan Acquisition - A'!M46 -> 380204.83 | H24: =sum(C24:G24) -> 842505.67 | J24: =H24/5 -> 168501.13
B25: Total Cash Outflow | C25: =Sum(C26:C28) -> 3000000 | D25: =Sum(D26:D28) -> 2000000 | E25: =Sum(E26:E28) -> 2000000 | F25: =Sum(F26:F28) -> 2000000 | G25: =Sum(G26:G28) -> 2000000 | H25: =sum(C25:G25) -> 11000000
B26: Customer licenses | C26: ='IT Cost Savings - Inputs and An'!E15 -> 1000000 | D26: ='IT Cost Savings - Inputs and An'!F15 -> 1500000 | E26: ='IT Cost Savings - Inputs and An'!G15 -> 1500000 | F26: ='IT Cost Savings - Inputs and An'!H15 -> 1500000 | G26: ='IT Cost Savings - Inputs and An'!I15 -> 1500000 | H26: =sum(C26:G26) -> 7000000
B27: Implementation costs (ITSS) | C27: ='IT Cost Savings - Inputs and An'!E16 -> 2000000 | D27: ='IT Cost Savings - Inputs and An'!F16 -> 500000 | E27: ='IT Cost Savings - Inputs and An'!G16 -> 500000 | F27: ='IT Cost Savings - Inputs and An'!H16 -> 500000 | G27: ='IT Cost Savings - Inputs and An'!I16 -> 500000 | H27: =sum(C27:G27) -> 4000000
B28: Manage and Hosting Costs | H28: =sum(C28:G28) -> 0
B30: Total Cash Flows | C30: =C14-C25 -> -2835467.4 | D30: =D14-D25 -> -294982.03 | E30: =E14-E25 -> 1331833.6 | F30: =F14-F25 -> 3895085.1 | G30: =G14-G25 -> 5178101.2 | H30: =sum(C30:G30) -> 7274570.4
B31: Present Value | C31: =C30/(1+$J$14)^0 -> -2835467.4 | D31: =D30/(1+$J$14)^1 -> -268165.48 | E31: =E30/(1+$J$14)^2 -> 1100689 | F31: =F30/(1+$J$14)^3 -> 2926435.1 | G31: =G30/(1+$J$14)^4 -> 3536712.8 | H31: =sum(C31:G31) -> 4460203.9
B32: Closing Balance | C32: =C30 -> -2835467.4 | D32: =C32+D30 -> -3130449.5 | E32: =D32+E30 -> -1798615.8 | F32: =E32+F30 -> 2096469.2 | G32: =F32+G30 -> 7274570.4 | H32: =sum(C32:G32) -> 1606506.9
C38: Year 1 | D38: Year 2 | E38: Year 3 | F38: Year 4 | G38: Year 5 | H38: Total
B39: Total Yearly Cash Inflow | C39: =C14 -> 164532.55 | D39: =D14 -> 1705018 | E39: =E14 -> 3331833.6 | F39: =F14 -> 5895085.1 | G39: =G14 -> 7178101.2 | H39: =sum(C39:G39) -> 18274570
B40: Total Cash Outflow | C40: =C30 -> -2835467.4 | D40: =D30 -> -294982.03 | E40: =E30 -> 1331833.6 | F40: =F30 -> 3895085.1 | G40: =G30 -> 5178101.2 | H40: =H30 -> 7274570.4
B41: Customer licenses | C41: =C26 -> 1000000 | D41: =D26 -> 1500000 | E41: =E26 -> 1500000 | F41: =F26 -> 1500000 | G41: =G26 -> 1500000 | H41: =sum(C41:G41) -> 7000000
B42: Implementation costs | C42: =C27 -> 2000000 | D42: =D27 -> 500000 | E42: =E27 -> 500000 | F42: =F27 -> 500000 | G42: =G27 -> 500000 | H42: =sum(C42:G42) -> 4000000
B43: Total Cash Flows | C43: =C29+C40 -> -2835467.4 | D43: =D29+D40 -> -294982.03 | E43: =E29+E40 -> 1331833.6 | F43: =F29+F40 -> 3895085.1 | G43: =G29+G40 -> 5178101.2 | H43: =sum(C43:G43) -> 7274570.4
B44: Present Value @ 10% | C44: =C43/(1+$J$14)^0 -> -2835467.4 | D44: =D43/(1+$J$14)^1 -> -268165.48 | E44: =E43/(1+$J$14)^2 -> 1100689 | F44: =F43/(1+$J$14)^3 -> 2926435.1 | G44: =G43/(1+$J$14)^4 -> 3536712.8 | H44: =sum(C44:G44) -> 4460203.9
B47: TOTAL RB+EB
C49: Year 1 | D49: Year 2 | E49: Year 3 | F49: Year 4 | G49: Year 5 | H49: Total
B50: RB:Total Yearly Cash Inflow | C50: =C39 -> 164532.55 | D50: =D39 -> 1705018 | E50: =E39 -> 3331833.6 | F50: =F39 -> 5895085.1 | G50: =G39 -> 7178101.2 | H50: =sum(C50:G50) -> 18274570
